Workbook

Sheet 01-05-26
A1: 酸轧线生产运行记录总表 สรุปการผลิต PK CRL Line
M2: 日期 (Date)
A3: 生产数据记录 บันทึกข้อมูลการผลิต | B3: 序号 Item | C3: 生产订单 Production Order | D3: 原料规格 size of material | E3: 原料重量 Weight of material（t） | F3: 原料卷数PK（coil） | G3: 成品规格 Description product | H3: 成品重量 weight of product (t) | I3: 成品卷数 CRL（coil） | J3: 各项指标及能源消耗 (ตัวชี้วัดและการใช้พลังงาน)
B5: 1 | C5: 138100000559 | D5: HRC 3.00 x 482 SPHC | E5: 329662 | F5: 58 | G5: CRC 1.11 x 482 SPCC | H5: 326532 | I5: 58 | J5: B级品 (เกรด B) | N5: 一级品率 (เกรด A)
B6: 2 | C6: 138100000561 | D6: HRC 3.40 x 479 SPHC | E6: 17225 | F6: 3 | G6: CRC 1.11 x 479 SPCC | H6: 17040 | I6: 3 | J6: 当日 /วัน（T） | L6: 16.806 | N6: 当日/ วัน（%） | O6: =(O9-L6)/O9 -> 0.95338685
B7: 3 | C7: 138100000557 | D7: HRC 3.50 x 470 SPHC | E7: 17187 | F7: 3 | G7: CRC 1.50 X 470 SPCC | H7: 16970 | I7: 3 | J7: 合计/ทั้งหมด（T） | L7: 16.806 | N7: 合计/ ทั้งหมด（%） | O7: =(O10-L7)/O10 -> 0.95338685
J8: 原料重量 (น้ำหนักวัตถุดิบ) PK | N8: 成品重量 (น้ำหนักวัตถุดิบ) CRL
J9: 当日（t） | L9: 364.074 | N9: 当日（t） | O9: 360.542
J10: 合计（t） | L10: 364.074 | N10: 合计（t） | O10: 360.542
J11: 机时产量(อัตราการผลิต/1ชั่วโมง) | N11: 有效作业率 (อัตราการทำงาน)
J12: 当日（t/h） | L12: =O9/(9-I33) -> 46.223333 | N12: 当日 （%） | O12: =(9-I33)/9 -> 0.86666667
J13: 合计（t/h） | L13: =O10/O46 -> 46.223333 | N13: 合计（%） | O13: =O46/L46 -> 0.86666667
J14: 酸洗电耗 ( ไฟฟ้า) PK
A15: 停机记录 บันทึกการหยุดเครื่อง | B15: 23:45 - 23:51换F4工作辊！ | H15: 分钟 | I15: 小时 | J15: 当日（kwh） | L15: 2573 | N15: 当日吨钢消耗 （kwh/t） | O15: =L15/L9 -> 7.0672446
H16: 6 | I16: =ROUND(H16/60,1) -> 0.1 | J16: 合计（kwh） | L16: 2573 | N16: 合计吨钢消耗 （kwh/t） | O16: =L16/L10 -> 7.0672446
B17: 2:13-2:18辊印更换F3工作辊！ | H17: 5 | I17: =ROUND(H17/60,1) -> 0.1 | J17: 盐酸 (HCL)
J18: 当日（m³） | L18: 7 | N18: 当日吨钢消耗 （m³/t） | O18: =L18/L9 -> 0.01922686
B19: 2:22-2:33焊接头开裂F3出口，更换F4工作辊！ | H19: 11 | I19: =ROUND(H19/60,1) -> 0.2 | J19: 合计（m³） | L19: 7 | N19: 合计吨钢消耗 （m³/t） | O19: =L19/L10 -> 0.01922686
J20: 原料打包带(น้ำหนักสายรัดวัตถุ) PK | N20: 焊接切除废料(เศษวัสดุหลังการเชื่อม)PK
B21: 2:55-3:10焊接头开裂3F出口，更换F4工作辊！ | H21: 15 | I21: =ROUND(H21/60,1) -> 0.3 | J21: 当日（kg） | L21: 232 | N21: 当日（kg） | O21: 256
J22: 合计（kg） | L22: 232 | N22: 合计（kg） | O22: 256
B23: 3:57-4:27焊接头开裂F2出口更换1.3.4架工作辊！ | H23: 30 | I23: =ROUND(H23/60,1) -> 0.5 | J23: 切头切尾 (scapหัว-ท้าย) | N23: 工艺段及活套废料 (เศษวัสดุจากกระบวนการผลิต)
J24: 当日（kg） | L24: 120 | N24: 当日（kg）
J25: 合计（kg） | L25: 120 | N25: 合计（kg）
J26: 酸洗天然气( แก๊ส PK)
J27: 当日（Nm3） | L27: 1202 | N27: 当日吨钢消耗 （Nm3/t） | O27: =L27/L9 -> 3.3015266
J28: 合计（Nm3） | L28: 1202 | N28: 合计吨钢消耗 （Nm3/t） | O28: =L28/L10 -> 3.3015266
J29: 缓蚀剂 (Actived 1803 )
J30: 当日（L） | L30: 21
J31: 合计(L) | L31: 21
J32: 轧机电耗 (ไฟฟ้า) CRL
I33: =ROUND(I16+I17+I19+I21+I23+I25+I27+I29+I31,1) -> 1.2 | J33: 当日（kwh） | L33: 14587 | N33: 当日吨钢消耗 （kwh/t） | O33: =L33/O9 -> 40.458532
J34: 合计（kwh） | L34: 14587 | N34: 合计吨钢消耗 （kwh/t） | O34: =L34/O10 -> 40.458532
A35: 质量概述 QC | B35: B级品：3卷边裂 | J35: 轧机废料 (เศษวัสดุจากเครื่องรีด) | N35: 成材率 (อัตราการผลิต)
J36: 断带废ของเสียจากสายพานขาด（kg） | L36: 342 | M36: 342 | N36: =L36/1000/L9 -> 0.00093936947 | O36: =M36/1000/L10 -> 0.00093936947
J37: 调整废（kg）ของเสียจากการปรับตั้ง | L37: 160 | M37: 160 | N37: =L37/1000/L9 -> 0.0004394711 | O37: =M37/1000/L10 -> 0.0004394711
J38: 孔洞、边裂（kg）ของเสียจากขอบแตก | L38: 126 | M38: 126 | N38: =L38/1000/L9 -> 0.00034608349 | O38: =M38/1000/L10 -> 0.00034608349
J39: 当日（kg） | L39: =L36+L37+L38 -> 628 | N39: 当日（%） | O39: =O9/L9 -> 0.99029868
J40: 合计（kg） | L40: 628 | N40: 合计（%） | O40: =(O10)/(L10-L22/1000) -> 0.99093013
J41: 轧制油 (Coolant)
...

Sheet 02-05-26
A1: 酸轧线生产运行记录总表 สรุปการผลิต PK CRL Line
M2: 日期 (Date)
A3: 生产数据记录 บันทึกข้อมูลการผลิต | B3: 序号 Item | C3: 生产订单 Production Order | D3: 原料规格 size of material | E3: 原料重量 Weight of material（t） | F3: 原料卷数PK（coil） | G3: 成品规格 Description product | H3: 成品重量 weight of product (t) | I3: 成品卷数 CRL（coil） | J3: 各项指标及能源消耗 (ตัวชี้วัดและการใช้พลังงาน)
B5: 1 | C5: 138100000557 | D5: HRC 3.50 x 470 SPHC | E5: 23007 | F5: 4 | G5: CRC 1.50 X 470 SPCC | H5: 22840 | I5: 4 | J5: B级品 (เกรด B) | N5: 一级品率 (เกรด A)
B6: 2 | C6: 138100000558 | D6: HRC 3.50 x 417 SPHC | E6: 40197 | F6: 8 | G6: CRC 1.50 x 417 SPCC | H6: 39800 | I6: 8 | J6: 当日 /วัน（T） | L6: 5.798 | N6: 当日/ วัน（%） | O6: =(O9-L6)/O9 -> 0.97851829
B7: 3 | C7: 138100000568 | D7: HRC 4.50 x 383 SPHC | E7: 104392 | F7: 23 | G7: CRC 2.90 x 383 SPCC | H7: 102202 | I7: 23 | J7: 合计/ทั้งหมด（T） | L7: =L6+'01-05-26'!L7:M7 -> 22.604 | N7: 合计/ ทั้งหมด（%） | O7: =(O10-L7)/O10 -> 0.96414602
B8: 4 | C8: 138100000539 | D8: HRC 3.50 x 457 SPHC | E8: 49153 | F8: 9 | G8: CRC 1.11 x 457 SPCC | H8: 48444 | I8: 9 | J8: 原料重量 (น้ำหนักวัตถุดิบ) PK | N8: 成品重量 (น้ำหนักวัตถุดิบ) CRL
B9: 5 | C9: 138100000540 | D9: HRC 3.00 x 439 SPHC | E9: 20476 | F9: 4 | G9: CRC 1.11 x 439 SPCC | H9: 20232 | I9: 4 | J9: 当日（t） | L9: 273.898 | N9: 当日（t） | O9: 269.904
B10: 6 | C10: 138100000541 | D10: HRC 3.00 x 439 SPHC | E10: 36673 | F10: 7 | G10: CRC 1.11 x 439 SPCC | H10: 36386 | I10: 7 | J10: 合计（t） | L10: =L9+'01-05-26'!L10:M10 -> 637.972 | N10: 合计（t） | O10: =O9+'01-05-26'!O10 -> 630.446
J11: 机时产量(อัตราการผลิต/1ชั่วโมง) | N11: 有效作业率 (อัตราการทำงาน)
J12: 当日（t/h） | L12: =O9/(8-I33) -> 40.894545 | N12: 当日 （%） | O12: =(8-I33)/8 -> 0.825
J13: 合计（t/h） | L13: =O10/O46 -> 43.780972 | N13: 合计（%） | O13: =O46/L46 -> 0.84705882
J14: 酸洗电耗 ( ไฟฟ้า) PK
A15: 停机记录 บันทึกการหยุดเครื่อง | B15: 22:22-22:27辊印更换F2工作辊！ | H15: 分钟 | I15: 小时 | J15: 当日（kwh） | L15: 2537 | N15: 当日吨钢消耗 （kwh/t） | O15: =L15/L9 -> 9.2625722
H16: 5 | I16: =ROUND(H16/60,1) -> 0.1 | J16: 合计（kwh） | L16: =L15+'01-05-26'!L16:M16 -> 5110 | N16: 合计吨钢消耗 （kwh/t） | O16: =L16/L10 -> 8.0097559
B17: 23:42-0:16改规格417*3.5*1.5改383*4.5*2.9轧机失涨，更换F4工作辊！ | H17: 34 | I17: =ROUND(H17/60,1) -> 0.6 | J17: 盐酸 (HCL)
J18: 当日（m³） | L18: 4 | N18: 当日吨钢消耗 （m³/t） | O18: =L18/L9 -> 0.014603977
B19: 3:08-3:30成品383*4.5*2.9头尾两卷改为2.2便于镀锌焊接F4轧机跳闸！ | H19: 22 | I19: =ROUND(H19/60,1) -> 0.4 | J19: 合计（m³） | L19: =L18+'01-05-26'!L19:M19 -> 11 | N19: 合计吨钢消耗 （m³/t） | O19: =L19/L10 -> 0.017242136
J20: 原料打包带(น้ำหนักสายรัดวัตถุ) PK | N20: 焊接切除废料(เศษวัสดุหลังการเชื่อม)PK
B21: 3:35-3:51窄带改宽带更换F1.3.4工作辊！ | H21: 16 | I21: =ROUND(H21/60,1) -> 0.3 | J21: 当日（kg） | L21: 266 | N21: 当日（kg） | O21: 284
J22: 合计（kg） | L22: =L21+'01-05-26'!L22:M22 -> 498 | N22: 合计（kg） | O22: =O21+'01-05-26'!O22 -> 540
J23: 切头切尾 (scapหัว-ท้าย) | N23: 工艺段及活套废料 (เศษวัสดุจากกระบวนการผลิต)
J24: 当日（kg） | L24: 196 | N24: 当日（kg）
J25: 合计（kg） | L25: =L24+'01-05-26'!L25:M25 -> 316 | N25: 合计（kg）
J26: 酸洗天然气( แก๊ส PK)
J27: 当日（Nm3） | L27: 1168 | N27: 当日吨钢消耗 （Nm3/t） | O27: =L27/L9 -> 4.2643612
J28: 合计（Nm3） | L28: =L27+'01-05-26'!L28:M28 -> 2370 | N28: 合计吨钢消耗 （Nm3/t） | O28: =L28/L10 -> 3.7148966
J29: 缓蚀剂 (Actived 1803 )
J30: 当日（L） | L30: 12
J31: 合计(L) | L31: =L30+'01-05-26'!L31:O31 -> 33
J32: 轧机电耗 (ไฟฟ้า) CRL
I33: =ROUND(I16+I17+I19+I21+I23+I25+I27+I29+I31,1) -> 1.4 | J33: 当日（kwh） | L33: 12198 | N33: 当日吨钢消耗 （kwh/t） | O33: =L33/O9 -> 45.193847
J34: 合计（kwh） | L34: =L33+'01-05-26'!L34:M34 -> 26785 | N34: 合计吨钢消耗 （kwh/t） | O34: =L34/O10 -> 42.485796
A35: 质量概述 QC | B35: B级品：边裂1卷 | J35: 轧机废料 (เศษวัสดุจากเครื่องรีด) | N35: 成材率 (อัตราการผลิต)
J36: 断带废ของเสียจากสายพานขาด（kg） | L36: 776 | M36: =L36+'01-05-26'!M36 -> 1118 | N36: =L36/1000/L9 -> 0.0028331715 | O36: =M36/1000/L10 -> 0.001752428
J37: 调整废（kg）ของเสียจากการปรับตั้ง | L37: 604 | M37: =L37+'01-05-26'!M37 -> 764 | N37: =L37/1000/L9 -> 0.0022052005 | O37: =M37/1000/L10 -> 0.0011975447
J38: 孔洞、边裂（kg）ของเสียจากขอบแตก | L38: 506 | M38: =L38+'01-05-26'!M38 -> 632 | N38: =L38/1000/L9 -> 0.001847403 | O38: =M38/1000/L10 -> 0.00099063909
J39: 当日（kg） | L39: =L36+L37+L38 -> 1886 | N39: 当日（%） | O39: =O9/L9 -> 0.98541793
J40: 合计（kg） | L40: =L39+'01-05-26'!L40:M40 -> 2514 | N40: 合计（%） | O40: =(O10)/(L10-L22/1000) -> 0.98897524
J41: 轧制油 (Coolant)
...

Sheet 03-05-26
A1: 酸轧线生产运行记录总表 สรุปการผลิต PK CRL Line
M2: 日期 (Date)
A3: 生产数据记录 บันทึกข้อมูลการผลิต | B3: 序号 Item | C3: 生产订单 Production Order | D3: 原料规格 size of material | E3: 原料重量 Weight of material（t） | F3: 原料卷数PK（coil） | G3: 成品规格 Description product | H3: 成品重量 weight of product (t) | I3: 成品卷数 CRL（coil） | J3: 各项指标及能源消耗 (ตัวชี้วัดและการใช้พลังงาน)
B5: 1 | C5: 138100000541 | D5: HRC 3.00 x 439 SPHC | E5: 141533 | F5: 27 | G5: CRC 1.11 x 439 SPCC | H5: 140408 | I5: 27 | J5: B级品 (เกรด B) | N5: 一级品率 (เกรด A)
B6: 2 | C6: 138100000542 | D6: HRC 3.00 x 437 SPHC | E6: 188794 | F6: 36 | G6: CRC 1.11 x 437 SPCC | H6: 187388 | I6: 36 | J6: 当日 /วัน（T） | L6: 15.756 | N6: 当日/ วัน（%） | O6: =(O9-L6)/O9 -> 0.96015356
B7: 3 | C7: 138100000543 | D7: HRC 3.00 x 437 SPHC | E7: 68172 | F7: 13 | G7: CRC 1.30 x 437 SPCC | H7: 67622 | I7: 13 | J7: 合计/ทั้งหมด（T） | L7: =L6+'02-05-26'!L7:M7 -> 38.36 | N7: 合计/ ทั้งหมด（%） | O7: =(O10-L7)/O10 -> 0.96260713
J8: 原料重量 (น้ำหนักวัตถุดิบ) PK | N8: 成品重量 (น้ำหนักวัตถุดิบ) CRL
J9: 当日（t） | L9: 398.499 | N9: 当日（t） | O9: 395.418
J10: 合计（t） | L10: =L9+'02-05-26'!L10:M10 -> 1036.471 | N10: 合计（t） | O10: =O9+'02-05-26'!O10 -> 1025.864
J11: 机时产量(อัตราการผลิต/1ชั่วโมง) | N11: 有效作业率 (อัตราการทำงาน)
J12: 当日（t/h） | L12: =O9/(9-I33) -> 48.817037 | N12: 当日 （%） | O12: =(9-I33)/9 -> 0.9
J13: 合计（t/h） | L13: =O10/O46 -> 45.593956 | N13: 合计（%） | O13: =O46/L46 -> 0.86538462
J14: 酸洗电耗 ( ไฟฟ้า) PK
A15: 停机记录 บันทึกการหยุดเครื่อง | B15: 22:15-22:20焊接头开裂F2出口！ | H15: 分钟 | I15: 小时 | J15: 当日（kwh） | L15: 2657 | N15: 当日吨钢消耗 （kwh/t） | O15: =L15/L9 -> 6.6675199
H16: 5 | I16: =ROUND(H16/60,1) -> 0.1 | J16: 合计（kwh） | L16: =L15+'02-05-26'!L16:M16 -> 7767 | N16: 合计吨钢消耗 （kwh/t） | O16: =L16/L10 -> 7.4936974
B17: 22:36-22:46调试自动焊机！ | H17: 10 | I17: =ROUND(H17/60,1) -> 0.2 | J17: 盐酸 (HCL)
J18: 当日（m³） | L18: 7 | N18: 当日吨钢消耗 （m³/t） | O18: =L18/L9 -> 0.017565916
B19: 1:39-1:43辊印更换F2工作辊！ | H19: 4 | I19: =ROUND(H19/60,1) -> 0.1 | J19: 合计（m³） | L19: =L18+'02-05-26'!L19:M19 -> 18 | N19: 合计吨钢消耗 （m³/t） | O19: =L19/L10 -> 0.017366622
J20: 原料打包带(น้ำหนักสายรัดวัตถุ) PK | N20: 焊接切除废料(เศษวัสดุหลังการเชื่อม)PK
B21: 2:16-2:23辊印更换F1工作辊！ | H21: 7 | I21: =ROUND(H21/60,1) -> 0.1 | J21: 当日（kg） | L21: 256 | N21: 当日（kg） | O21: 290
J22: 合计（kg） | L22: =L21+'02-05-26'!L22:M22 -> 754 | N22: 合计（kg） | O22: =O21+'02-05-26'!O22 -> 830
B23: 3:11-3:16辊印更换F3工作辊！ | H23: 5 | I23: =ROUND(H23/60,1) -> 0.1 | J23: 切头切尾 (scapหัว-ท้าย) | N23: 工艺段及活套废料 (เศษวัสดุจากกระบวนการผลิต)
J24: 当日（kg） | L24: 134 | N24: 当日（kg）
B25: 6:40-7:00辊印更换F4工作辊！ | H25: 20 | I25: =ROUND(H25/60,1) -> 0.3 | J25: 合计（kg） | L25: =L24+'02-05-26'!L25:M25 -> 450 | N25: 合计（kg）
J26: 酸洗天然气( แก๊ส PK)
J27: 当日（Nm3） | L27: 1255 | N27: 当日吨钢消耗 （Nm3/t） | O27: =L27/L9 -> 3.1493178
J28: 合计（Nm3） | L28: =L27+'02-05-26'!L28:M28 -> 3625 | N28: 合计吨钢消耗 （Nm3/t） | O28: =L28/L10 -> 3.4974447
J29: 缓蚀剂 (Actived 1803 )
J30: 当日（L） | L30: 21
J31: 合计(L) | L31: =L30+'02-05-26'!L31:O31 -> 54
J32: 轧机电耗 (ไฟฟ้า) CRL
I33: =ROUND(I16+I17+I19+I21+I23+I25+I27+I29+I31,1) -> 0.9 | J33: 当日（kwh） | L33: 18165 | N33: 当日吨钢消耗 （kwh/t） | O33: =L33/O9 -> 45.938728
J34: 合计（kwh） | L34: =L33+'02-05-26'!L34:M34 -> 44950 | N34: 合计吨钢消耗 （kwh/t） | O34: =L34/O10 -> 43.816724
A35: 质量概述 QC | B35: B级品：边裂3卷！ | J35: 轧机废料 (เศษวัสดุจากเครื่องรีด) | N35: 成材率 (อัตราการผลิต)
J36: 断带废ของเสียจากสายพานขาด（kg） | L36: 152 | M36: =L36+'02-05-26'!M36 -> 1270 | N36: =L36/1000/L9 -> 0.00038143132 | O36: =M36/1000/L10 -> 0.0012253117
J37: 调整废（kg）ของเสียจากการปรับตั้ง | L37: 41 | M37: =L37+'02-05-26'!M37 -> 805 | N37: =L37/1000/L9 -> 0.00010288608 | O37: =M37/1000/L10 -> 0.00077667393
J38: 孔洞、边裂（kg）ของเสียจากขอบแตก | L38: 100 | M38: =L38+'02-05-26'!M38 -> 732 | N38: =L38/1000/L9 -> 0.00025094166 | O38: =M38/1000/L10 -> 0.00070624263
J39: 当日（kg） | L39: =L36+L37+L38 -> 293 | N39: 当日（%） | O39: =O9/L9 -> 0.99226849
J40: 合计（kg） | L40: =L39+'02-05-26'!L40:M40 -> 2807 | N40: 合计（%） | O40: =(O10)/(L10-L22/1000) -> 0.99048678
J41: 轧制油 (Coolant)
...

Sheet 04-05-26
A1: 酸轧线生产运行记录总表 สรุปการผลิต PK CRL Line
M2: 日期 (Date)
A3: 生产数据记录 บันทึกข้อมูลการผลิต | B3: 序号 Item | C3: 生产订单 Production Order | D3: 原料规格 size of material | E3: 原料重量 Weight of material（t） | F3: 原料卷数PK（coil） | G3: 成品规格 Description product | H3: 成品重量 weight of product (t) | I3: 成品卷数 CRL（coil） | J3: 各项指标及能源消耗 (ตัวชี้วัดและการใช้พลังงาน)
B5: 1 | C5: 138100000543 | D5: HRC 3.00 x 437 SPHC | E5: 404525 | F5: 77 | G5: CRC 1.30 x 437 SPCC | H5: 401220 | I5: 77 | J5: B级品 (เกรด B) | N5: 一级品率 (เกรด A)
J6: 当日 /วัน（T） | L6: 10.34 | N6: 当日/ วัน（%） | O6: =(O9-L6)/O9 -> 0.9742286
J7: 合计/ทั้งหมด（T） | L7: =L6+'03-05-26'!L7:M7 -> 48.7 | N7: 合计/ ทั้งหมด（%） | O7: =(O10-L7)/O10 -> 0.96587447
J8: 原料重量 (น้ำหนักวัตถุดิบ) PK | N8: 成品重量 (น้ำหนักวัตถุดิบ) CRL
J9: 当日（t） | L9: 404.525 | N9: 当日（t） | O9: 401.22
J10: 合计（t） | L10: =L9+'03-05-26'!L10:M10 -> 1440.996 | N10: 合计（t） | O10: =O9+'03-05-26'!O10 -> 1427.084
J11: 机时产量(อัตราการผลิต/1ชั่วโมง) | N11: 有效作业率 (อัตราการทำงาน)
J12: 当日（t/h） | L12: =O9/(9-I33) -> 47.764286 | N12: 当日 （%） | O12: =(9-I33)/9 -> 0.93333333
J13: 合计（t/h） | L13: =O10/O46 -> 46.183948 | N13: 合计（%） | O13: =O46/L46 -> 0.88285714
J14: 酸洗电耗 ( ไฟฟ้า) PK
A15: 停机记录 บันทึกการหยุดเครื่อง | B15: 0:14-0:25更换自动焊机焊丝！ | H15: 分钟 | I15: 小时 | J15: 当日（kwh） | L15: 2669 | N15: 当日吨钢消耗 （kwh/t） | O15: =L15/L9 -> 6.5978617
H16: 11 | I16: =ROUND(H16/60,1) -> 0.2 | J16: 合计（kwh） | L16: =L15+'03-05-26'!L16:M16 -> 10436 | N16: 合计吨钢消耗 （kwh/t） | O16: =L16/L10 -> 7.242213
B17: 6:36-7:00辊印更换F1.F2工作辊！ | H17: 24 | I17: =ROUND(H17/60,1) -> 0.4 | J17: 盐酸 (HCL)
J18: 当日（m³） | L18: 7 | N18: 当日吨钢消耗 （m³/t） | O18: =L18/L9 -> 0.017304246
J19: 合计（m³） | L19: =L18+'03-05-26'!L19:M19 -> 25 | N19: 合计吨钢消耗 （m³/t） | O19: =L19/L10 -> 0.017349111
J20: 原料打包带(น้ำหนักสายรัดวัตถุ) PK | N20: 焊接切除废料(เศษวัสดุหลังการเชื่อม)PK
J21: 当日（kg） | L21: 292 | N21: 当日（kg） | O21: 340
J22: 合计（kg） | L22: =L21+'03-05-26'!L22:M22 -> 1046 | N22: 合计（kg） | O22: =O21+'03-05-26'!O22 -> 1170
J23: 切头切尾 (scapหัว-ท้าย) | N23: 工艺段及活套废料 (เศษวัสดุจากกระบวนการผลิต)
J24: 当日（kg） | L24: 126 | N24: 当日（kg）
J25: 合计（kg） | L25: =L24+'03-05-26'!L25:M25 -> 576 | N25: 合计（kg）
J26: 酸洗天然气( แก๊ส PK)
J27: 当日（Nm3） | L27: 1280 | N27: 当日吨钢消耗 （Nm3/t） | O27: =L27/L9 -> 3.1642049
J28: 合计（Nm3） | L28: =L27+'03-05-26'!L28:M28 -> 4905 | N28: 合计吨钢消耗 （Nm3/t） | O28: =L28/L10 -> 3.4038956
J29: 缓蚀剂 (Actived 1803 )
J30: 当日（L） | L30: 21
J31: 合计(L) | L31: =L30+'03-05-26'!L31:O31 -> 75
J32: 轧机电耗 (ไฟฟ้า) CRL
I33: =ROUND(I16+I17+I19+I21+I23+I25+I27+I29+I31,1) -> 0.6 | J33: 当日（kwh） | L33: 16129 | N33: 当日吨钢消耗 （kwh/t） | O33: =L33/O9 -> 40.19989
J34: 合计（kwh） | L34: =L33+'03-05-26'!L34:M34 -> 61079 | N34: 合计吨钢消耗 （kwh/t） | O34: =L34/O10 -> 42.799863
A35: 质量概述 QC | B35: B级品：边裂2卷！ | J35: 轧机废料 (เศษวัสดุจากเครื่องรีด) | N35: 成材率 (อัตราการผลิต)
J36: 断带废ของเสียจากสายพานขาด（kg） | L36: 0 | M36: =L36+'03-05-26'!M36 -> 1270 | N36: =L36/1000/L9 -> 0 | O36: =M36/1000/L10 -> 0.00088133485
J37: 调整废（kg）ของเสียจากการปรับตั้ง | L37: 216 | M37: =L37+'03-05-26'!M37 -> 1021 | N37: =L37/1000/L9 -> 0.00053395958 | O37: =M37/1000/L10 -> 0.00070853771
J38: 孔洞、边裂（kg）ของเสียจากขอบแตก | L38: 202 | M38: =L38+'03-05-26'!M38 -> 934 | N38: =L38/1000/L9 -> 0.00049935109 | O38: =M38/1000/L10 -> 0.0006481628
J39: 当日（kg） | L39: =L36+L37+L38 -> 418 | N39: 当日（%） | O39: =O9/L9 -> 0.99182992
J40: 合计（kg） | L40: =L39+'03-05-26'!L40:M40 -> 3225 | N40: 合计（%） | O40: =(O10)/(L10-L22/1000) -> 0.99106497
J41: 轧制油 (Coolant)
...

Sheet 05-05-26
A1: 酸轧线生产运行记录总表 สรุปการผลิต PK CRL Line
M2: 日期 (Date)
A3: 生产数据记录 บันทึกข้อมูลการผลิต | B3: 序号 Item | C3: 生产订单 Production Order | D3: 原料规格 size of material | E3: 原料重量 Weight of material（t） | F3: 原料卷数PK（coil） | G3: 成品规格 Description product | H3: 成品重量 weight of product (t) | I3: 成品卷数 CRL（coil） | J3: 各项指标及能源消耗 (ตัวชี้วัดและการใช้พลังงาน)
B5: 1 | C5: 138100000543 | D5: HRC 3.00 x 437 SPHC | E5: 293595 | F5: 56 | G5: CRC 1.30 x 437 SPCC | H5: 291298 | I5: 56 | J5: B级品 (เกรด B) | N5: 一级品率 (เกรด A)
B6: 2 | C6: 138100000544 | D6: HRC 3.60 x 439 SPHC | E6: 5210 | F6: 1 | G6: CRC 1.30 x 437 SPCC | H6: 5150 | I6: 1 | J6: 当日 /วัน（T） | L6: 25.916 | N6: 当日/ วัน（%） | O6: =(O9-L6)/O9 -> 0.93525985
B7: 3 | C7: 138100000541 | D7: HRC 3.00 x 439 SPHC | E7: 15932 | F7: 3 | G7: CRC 1.11 x 439 SPCC | H7: 15798 | I7: 3 | J7: 合计/ทั้งหมด（T） | L7: =L6+'04-05-26'!L7:M7 -> 74.616 | N7: 合计/ ทั้งหมด（%） | O7: =(O10-L7)/O10 -> 0.95916804
B8: 4 | C8: 138100000548 | D8: HRC 3.00 x 434 SPHC | E8: 88810 | F8: 17 | G8: CRC 1.11 x 434 SPCC | H8: 88062 | I8: 17 | J8: 原料重量 (น้ำหนักวัตถุดิบ) PK | N8: 成品重量 (น้ำหนักวัตถุดิบ) CRL
J9: 当日（t） | L9: 403.547 | N9: 当日（t） | O9: 400.308
J10: 合计（t） | L10: =L9+'04-05-26'!L10:M10 -> 1844.543 | N10: 合计（t） | O10: =O9+'04-05-26'!O10 -> 1827.392
J11: 机时产量(อัตราการผลิต/1ชั่วโมง) | N11: 有效作业率 (อัตราการทำงาน)
J12: 当日（t/h） | L12: =O9/(9-I33) -> 46.012414 | N12: 当日 （%） | O12: =(9-I33)/9 -> 0.96666667
J13: 合计（t/h） | L13: =O10/O46 -> 46.146263 | N13: 合计（%） | O13: =O46/L46 -> 0.9
J14: 酸洗电耗 ( ไฟฟ้า) PK
A15: 停机记录 บันทึกการหยุดเครื่อง | B15: 23:20-23:28处理1号收卷机液压阀台漏油！ | H15: 分钟 | I15: 小时 | J15: 当日（kwh） | L15: 2628 | N15: 当日吨钢消耗 （kwh/t） | O15: =L15/L9 -> 6.5122526
H16: 8 | I16: =ROUND(H16/60,1) -> 0.1 | J16: 合计（kwh） | L16: =L15+'04-05-26'!L16:M16 -> 13064 | N16: 合计吨钢消耗 （kwh/t） | O16: =L16/L10 -> 7.0825131
B17: 3:16-3:22辊印更换F3工作辊！ | H17: 6 | I17: =ROUND(H17/60,1) -> 0.1 | J17: 盐酸 (HCL)
J18: 当日（m³） | L18: 10 | N18: 当日吨钢消耗 （m³/t） | O18: =L18/L9 -> 0.024780261
B19: 3:53-3:58调试自动焊机！ | H19: 5 | I19: =ROUND(H19/60,1) -> 0.1 | J19: 合计（m³） | L19: =L18+'04-05-26'!L19:M19 -> 35 | N19: 合计吨钢消耗 （m³/t） | O19: =L19/L10 -> 0.01897489
J20: 原料打包带(น้ำหนักสายรัดวัตถุ) PK | N20: 焊接切除废料(เศษวัสดุหลังการเชื่อม)PK
B21: 4:40-4:46辊印更换F4工作辊！ | H21: 6 | I21: =ROUND(H21/60,1) -> 0.1 | J21: 当日（kg） | L21: 280 | N21: 当日（kg） | O21: 350
J22: 合计（kg） | L22: =L21+'04-05-26'!L22:M22 -> 1326 | N22: 合计（kg） | O22: =O21+'04-05-26'!O22 -> 1520
J23: 切头切尾 (scapหัว-ท้าย) | N23: 工艺段及活套废料 (เศษวัสดุจากกระบวนการผลิต)
J24: 当日（kg） | L24: 140 | N24: 当日（kg）
J25: 合计（kg） | L25: =L24+'04-05-26'!L25:M25 -> 716 | N25: 合计（kg）
J26: 酸洗天然气( แก๊ส PK)
J27: 当日（Nm3） | L27: 1310 | N27: 当日吨钢消耗 （Nm3/t） | O27: =L27/L9 -> 3.2462142
J28: 合计（Nm3） | L28: =L27+'04-05-26'!L28:M28 -> 6215 | N28: 合计吨钢消耗 （Nm3/t） | O28: =L28/L10 -> 3.3693983
J29: 缓蚀剂 (Actived 1803 )
J30: 当日（L） | L30: 30
J31: 合计(L) | L31: =L30+'04-05-26'!L31:O31 -> 105
J32: 轧机电耗 (ไฟฟ้า) CRL
I33: =ROUND(I16+I17+I19+I22+I23+I25+I27+I29+I31,1) -> 0.3 | J33: 当日（kwh） | L33: 16777 | N33: 当日吨钢消耗 （kwh/t） | O33: =L33/O9 -> 41.910229
J34: 合计（kwh） | L34: =L33+'04-05-26'!L34:M34 -> 77856 | N34: 合计吨钢消耗 （kwh/t） | O34: =L34/O10 -> 42.60498
A35: 质量概述 QC | B35: B级品：4卷原料边裂，1卷带尾氧化皮，共5卷！ | J35: 轧机废料 (เศษวัสดุจากเครื่องรีด) | N35: 成材率 (อัตราการผลิต)
J36: 断带废ของเสียจากสายพานขาด（kg） | L36: 0 | M36: =L36+'04-05-26'!M36 -> 1270 | N36: =L36/1000/L9 -> 0 | O36: =M36/1000/L10 -> 0.00068851743
J37: 调整废（kg）ของเสียจากการปรับตั้ง | L37: 86 | M37: =L37+'04-05-26'!M37 -> 1107 | N37: =L37/1000/L9 -> 0.00021311024 | O37: =M37/1000/L10 -> 0.00060014865
J38: 孔洞、边裂（kg）ของเสียจากขอบแตก | L38: 181 | M38: =L38+'04-05-26'!M38 -> 1115 | N38: =L38/1000/L9 -> 0.00044852272 | O38: =M38/1000/L10 -> 0.00060448577
J39: 当日（kg） | L39: =L36+L37+L38 -> 267 | N39: 当日（%） | O39: =O9/L9 -> 0.99197367
J40: 合计（kg） | L40: =L39+'04-05-26'!L40:M40 -> 3492 | N40: 合计（%） | O40: =(O10)/(L10-L22/1000) -> 0.99141447
J41: 轧制油 (Coolant)
...

Sheet 06-05-26
A1: 酸轧线生产运行记录总表 สรุปการผลิต PK CRL Line
M2: 日期 (Date)
A3: 生产数据记录 บันทึกข้อมูลการผลิต | B3: 序号 Item | C3: 生产订单 Production Order | D3: 原料规格 size of material | E3: 原料重量 Weight of material（t） | F3: 原料卷数PK（coil） | G3: 成品规格 Description product | H3: 成品重量 weight of product (t) | I3: 成品卷数 CRL（coil） | J3: 各项指标及能源消耗 (ตัวชี้วัดและการใช้พลังงาน)
B5: 1 | C5: 138100000548 | D5: HRC 3.00 x 434 SPHC | E5: 488942 | F5: 93 | G5: CRC 1.11 x 434 SPCC | H5: 484822 | I5: 93 | J5: B级品 (เกรด B) | N5: 一级品率 (เกรด A)
B6: 2 | C6: 138100000546 | D6: HRC 3.00 x 434 SPHC | E6: 26345 | F6: 5 | G6: CRC 1.30 x 434 SPCC | H6: 26132 | I6: 5 | J6: 当日 /วัน（T） | L6: 31.296 | N6: 当日/ วัน（%） | O6: =(O9-L6)/O9 -> 0.93874987
J7: 合计/ทั้งหมด（T） | L7: =L6+'05-05-26'!L7:M7 -> 105.912 | N7: 合计/ ทั้งหมด（%） | O7: =(O10-L7)/O10 -> 0.95470645
J8: 原料重量 (น้ำหนักวัตถุดิบ) PK | N8: 成品重量 (น้ำหนักวัตถุดิบ) CRL
J9: 当日（t） | L9: 515.287 | N9: 当日（t） | O9: 510.954
J10: 合计（t） | L10: =L9+'05-05-26'!L10:M10 -> 2359.83 | N10: 合计（t） | O10: =O9+'05-05-26'!O10 -> 2338.346
J11: 机时产量(อัตราการผลิต/1ชั่วโมง) | N11: 有效作业率 (อัตราการทำงาน)
J12: 当日（t/h） | L12: =O9/(11-I33) -> 47.75271 | N12: 当日 （%） | O12: =(11-I33)/11 -> 0.97272727
J13: 合计（t/h） | L13: =O10/O46 -> 46.487992 | N13: 合计（%） | O13: =O46/L46 -> 0.91454545
J14: 酸洗电耗 ( ไฟฟ้า) PK
A15: 停机记录 บันทึกการหยุดเครื่อง | B15: 22:49-22:54辊印更换F4工作辊！ | H15: 分钟 | I15: 小时 | J15: 当日（kwh） | L15: 3155 | N15: 当日吨钢消耗 （kwh/t） | O15: =L15/L9 -> 6.1228015
H16: 5 | I16: =ROUND(H16/60,1) -> 0.1 | J16: 合计（kwh） | L16: =L15+'05-05-26'!L16:M16 -> 16219 | N16: 合计吨钢消耗 （kwh/t） | O16: =L16/L10 -> 6.8729527
B17: 1:24-1:28自动焊机调试！ | H17: 4 | I17: =ROUND(H17/60,1) -> 0.1 | J17: 盐酸 (HCL)
J18: 当日（m³） | L18: 12 | N18: 当日吨钢消耗 （m³/t） | O18: =L18/L9 -> 0.023287993
B19: 3:35-3:41辊印更换F1工作辊！ | H19: 6 | I19: =ROUND(H19/60,1) -> 0.1 | J19: 合计（m³） | L19: =L18+'05-05-26'!L19:M19 -> 47 | N19: 合计吨钢消耗 （m³/t） | O19: =L19/L10 -> 0.019916689
J20: 原料打包带(น้ำหนักสายรัดวัตถุ) PK | N20: 焊接切除废料(เศษวัสดุหลังการเชื่อม)PK
B21: 8:40-9:00更换F2.3工作辊！ | H21: 20 | I21: =ROUND(H21/60,1) -> 0.3 | J21: 当日（kg） | L21: 400 | N21: 当日（kg） | O21: 400
J22: 合计（kg） | L22: =L21+'05-05-26'!L22:M22 -> 1726 | N22: 合计（kg） | O22: =O21+'05-05-26'!O22 -> 1920
J23: 切头切尾 (scapหัว-ท้าย) | N23: 工艺段及活套废料 (เศษวัสดุจากกระบวนการผลิต)
J24: 当日（kg） | L24: 270 | N24: 当日（kg）
J25: 合计（kg） | L25: =L24+'05-05-26'!L25:M25 -> 986 | N25: 合计（kg）
J26: 酸洗天然气( แก๊ส PK)
J27: 当日（Nm3） | L27: 1497 | N27: 当日吨钢消耗 （Nm3/t） | O27: =L27/L9 -> 2.9051771
J28: 合计（Nm3） | L28: =L27+'05-05-26'!L28:M28 -> 7712 | N28: 合计吨钢消耗 （Nm3/t） | O28: =L28/L10 -> 3.268032
J29: 缓蚀剂 (Actived 1803 )
J30: 当日（L） | L30: 36
J31: 合计(L) | L31: =L30+'05-05-26'!L31:O31 -> 141
J32: 轧机电耗 (ไฟฟ้า) CRL
I33: =ROUND(I16+I17+I19+I22+I23+I25+I27+I29+I31,1) -> 0.3 | J33: 当日（kwh） | L33: 22109 | N33: 当日吨钢消耗 （kwh/t） | O33: =L33/O9 -> 43.27004
J34: 合计（kwh） | L34: =L33+'05-05-26'!L34:M34 -> 99965 | N34: 合计吨钢消耗 （kwh/t） | O34: =L34/O10 -> 42.750303
A35: 质量概述 QC | B35: B级品：6卷原料边裂！ | J35: 轧机废料 (เศษวัสดุจากเครื่องรีด) | N35: 成材率 (อัตราการผลิต)
J36: 断带废ของเสียจากสายพานขาด（kg） | L36: 219 | M36: =L36+'05-05-26'!M36 -> 1489 | N36: =L36/1000/L9 -> 0.00042500587 | O36: =M36/1000/L10 -> 0.00063097766
J37: 调整废（kg）ของเสียจากการปรับตั้ง | L37: 120 | M37: =L37+'05-05-26'!M37 -> 1227 | N37: =L37/1000/L9 -> 0.00023287993 | O37: =M37/1000/L10 -> 0.00051995271
J38: 孔洞、边裂（kg）ของเสียจากขอบแตก | L38: 122 | M38: =L38+'05-05-26'!M38 -> 1237 | N38: =L38/1000/L9 -> 0.00023676126 | O38: =M38/1000/L10 -> 0.0005241903
J39: 当日（kg） | L39: =L36+L37+L38 -> 461 | N39: 当日（%） | O39: =O9/L9 -> 0.99159109
J40: 合计（kg） | L40: =L39+'05-05-26'!L40:M40 -> 3953 | N40: 合计（%） | O40: =(O10)/(L10-L22/1000) -> 0.99162123
J41: 轧制油 (Coolant)
...

Sheet 07-05-26
A1: 酸轧线生产运行记录总表 สรุปการผลิต PK CRL Line
M2: 日期 (Date)
A3: 生产数据记录 บันทึกข้อมูลการผลิต | B3: 序号 Item | C3: 生产订单 Production Order | D3: 原料规格 size of material | E3: 原料重量 Weight of material（t） | F3: 原料卷数PK（coil） | G3: 成品规格 Description product | H3: 成品重量 weight of product (t) | I3: 成品卷数 CRL（coil） | J3: 各项指标及能源消耗 (ตัวชี้วัดและการใช้พลังงาน)
B5: 1 | C5: 138100000546 | D5: HRC 3.00 x 434 SPHC | E5: 509262 | F5: 97 | G5: CRC 1.30 x 434 SPCC | H5: 505212 | I5: 97 | J5: B级品 (เกรด B) | N5: 一级品率 (เกรด A)
J6: 当日 /วัน（T） | L6: 10.46 | N6: 当日/ วัน（%） | O6: =(O9-L6)/O9 -> 0.97929582
J7: 合计/ทั้งหมด（T） | L7: =L6+'06-05-26'!L7:M7 -> 116.372 | N7: 合计/ ทั้งหมด（%） | O7: =(O10-L7)/O10 -> 0.95907521
J8: 原料重量 (น้ำหนักวัตถุดิบ) PK | N8: 成品重量 (น้ำหนักวัตถุดิบ) CRL
J9: 当日（t） | L9: 509.262 | N9: 当日（t） | O9: 505.212
J10: 合计（t） | L10: =L9+'06-05-26'!L10:M10 -> 2869.092 | N10: 合计（t） | O10: =O9+'06-05-26'!O10 -> 2843.558
J11: 机时产量(อัตราการผลิต/1ชั่วโมง) | N11: 有效作业率 (อัตราการทำงาน)
J12: 当日（t/h） | L12: =O9/(11-I33) -> 47.661509 | N12: 当日 （%） | O12: =(11-I33)/11 -> 0.96363636
J13: 合计（t/h） | L13: =O10/O46 -> 46.69225 | N13: 合计（%） | O13: =O46/L46 -> 0.92272727
J14: 酸洗电耗 ( ไฟฟ้า) PK
A15: 停机记录 บันทึกการหยุดเครื่อง | B15: 23:50-23:56调试自动焊机！ | H15: 分钟 | I15: 小时 | J15: 当日（kwh） | L15: 3236 | N15: 当日吨钢消耗 （kwh/t） | O15: =L15/L9 -> 6.3542931
H16: 6 | I16: =ROUND(H16/60,1) -> 0.1 | J16: 合计（kwh） | L16: =L15+'06-05-26'!L16:M16 -> 19455 | N16: 合计吨钢消耗 （kwh/t） | O16: =L16/L10 -> 6.780891
B17: 0:23-0:28辊印更换F1工作辊！ | H17: 5 | I17: =ROUND(H17/60,1) -> 0.1 | J17: 盐酸 (HCL)
J18: 当日（m³） | L18: 10 | N18: 当日吨钢消耗 （m³/t） | O18: =L18/L9 -> 0.019636258
B19: 7:24-7:33处理原料镰刀弯，越10米左右！ | H19: 9 | I19: =ROUND(H19/60,1) -> 0.2 | J19: 合计（m³） | L19: =L18+'06-05-26'!L19:M19 -> 57 | N19: 合计吨钢消耗 （m³/t） | O19: =L19/L10 -> 0.019866913
J20: 原料打包带(น้ำหนักสายรัดวัตถุ) PK | N20: 焊接切除废料(เศษวัสดุหลังการเชื่อม)PK
B21: 8:40-9:00更换F2.F4工作辊！ | H21: 20 | I21: =ROUND(H21/60,1) -> 0.3 | J21: 当日（kg） | L21: 394 | N21: 当日（kg） | O21: 440
J22: 合计（kg） | L22: =L21+'06-05-26'!L22:M22 -> 2120 | N22: 合计（kg） | O22: =O21+'06-05-26'!O22 -> 2360
J23: 切头切尾 (scapหัว-ท้าย) | N23: 工艺段及活套废料 (เศษวัสดุจากกระบวนการผลิต)
J24: 当日（kg） | L24: 165 | N24: 当日（kg）
J25: 合计（kg） | L25: =L24+'06-05-26'!L25:M25 -> 1151 | N25: 合计（kg）
J26: 酸洗天然气( แก๊ส PK)
J27: 当日（Nm3） | L27: 1517 | N27: 当日吨钢消耗 （Nm3/t） | O27: =L27/L9 -> 2.9788203
J28: 合计（Nm3） | L28: =L27+'06-05-26'!L28:M28 -> 9229 | N28: 合计吨钢消耗 （Nm3/t） | O28: =L28/L10 -> 3.2166971
J29: 缓蚀剂 (Actived 1803 )
J30: 当日（L） | L30: 30
J31: 合计(L) | L31: =L30+'06-05-26'!L31:O31 -> 171
J32: 轧机电耗 (ไฟฟ้า) CRL
I33: =ROUND(I16+I17+I19+I22+I23+I25+I27+I29+I31,1) -> 0.4 | J33: 当日（kwh） | L33: 19973 | N33: 当日吨钢消耗 （kwh/t） | O33: =L33/O9 -> 39.533899
J34: 合计（kwh） | L34: =L33+'06-05-26'!L34:M34 -> 119938 | N34: 合计吨钢消耗 （kwh/t） | O34: =L34/O10 -> 42.178848
A35: 质量概述 QC | B35: 边裂2卷！ | J35: 轧机废料 (เศษวัสดุจากเครื่องรีด) | N35: 成材率 (อัตราการผลิต)
J36: 断带废ของเสียจากสายพานขาด（kg） | L36: 0 | M36: =L36+'06-05-26'!M36 -> 1489 | N36: =L36/1000/L9 -> 0 | O36: =M36/1000/L10 -> 0.00051897952
J37: 调整废（kg）ของเสียจากการปรับตั้ง | L37: 98 | M37: =L37+'06-05-26'!M37 -> 1325 | N37: =L37/1000/L9 -> 0.00019243533 | O37: =M37/1000/L10 -> 0.00046181858
J38: 孔洞、边裂（kg）ของเสียจากขอบแตก | L38: 120 | M38: =L38+'06-05-26'!M38 -> 1357 | N38: =L38/1000/L9 -> 0.0002356351 | O38: =M38/1000/L10 -> 0.00047297194
J39: 当日（kg） | L39: =L36+L37+L38 -> 218 | N39: 当日（%） | O39: =O9/L9 -> 0.99204732
J40: 合计（kg） | L40: =L39+'06-05-26'!L40:M40 -> 4171 | N40: 合计（%） | O40: =(O10)/(L10-L22/1000) -> 0.9918332
J41: 轧制油 (Coolant)
...

Sheet 08-05-26
A1: 酸轧线生产运行记录总表 สรุปการผลิต PK CRL Line
M2: 日期 (Date)
A3: 生产数据记录 บันทึกข้อมูลการผลิต | B3: 序号 Item | C3: 生产订单 Production Order | D3: 原料规格 size of material | E3: 原料重量 Weight of material（t） | F3: 原料卷数PK（coil） | G3: 成品规格 Description product | H3: 成品重量 weight of product (t) | I3: 成品卷数 CRL（coil） | J3: 各项指标及能源消耗 (ตัวชี้วัดและการใช้พลังงาน)
B5: 1 | C5: 138100000546 | D5: HRC 3.00 x 434 SPHC | E5: 501506 | F5: 96 | G5: CRC 1.30 x 434 SPCC | H5: 497584 | I5: 96 | J5: B级品 (เกรด B) | N5: 一级品率 (เกรด A)
J6: 当日 /วัน（T） | L6: 5.144 | N6: 当日/ วัน（%） | O6: =(O9-L6)/O9 -> 0.98966205
J7: 合计/ทั้งหมด（T） | L7: =L6+'07-05-26'!L7:M7 -> 121.516 | N7: 合计/ ทั้งหมด（%） | O7: =(O10-L7)/O10 -> 0.9636304
J8: 原料重量 (น้ำหนักวัตถุดิบ) PK | N8: 成品重量 (น้ำหนักวัตถุดิบ) CRL
J9: 当日（t） | L9: 501.506 | N9: 当日（t） | O9: 497.584
J10: 合计（t） | L10: =L9+'07-05-26'!L10:M10 -> 3370.598 | N10: 合计（t） | O10: =O9+'07-05-26'!O10 -> 3341.142
J11: 机时产量(อัตราการผลิต/1ชั่วโมง) | N11: 有效作业率 (อัตราการทำงาน)
J12: 当日（t/h） | L12: =O9/(11-I33) -> 46.503178 | N12: 当日 （%） | O12: =(11-I33)/11 -> 0.97272727
J13: 合计（t/h） | L13: =O10/O46 -> 46.663994 | N13: 合计（%） | O13: =O46/L46 -> 0.92987013
J14: 酸洗电耗 ( ไฟฟ้า) PK
A15: 停机记录 บันทึกการหยุดเครื่อง | B15: 0:26-0:31自动焊机调试！ | H15: 分钟 | I15: 小时 | J15: 当日（kwh） | L15: 3214 | N15: 当日吨钢消耗 （kwh/t） | O15: =L15/L9 -> 6.408697
H16: 5 | I16: =ROUND(H16/60,1) -> 0.1 | J16: 合计（kwh） | L16: =L15+'07-05-26'!L16:M16 -> 22669 | N16: 合计吨钢消耗 （kwh/t） | O16: =L16/L10 -> 6.7255128
B17: 3:55-4:01辊印更换F1工作辊！ | H17: 6 | I17: =ROUND(H17/60,1) -> 0.1 | J17: 盐酸 (HCL)
J18: 当日（m³） | L18: 10 | N18: 当日吨钢消耗 （m³/t） | O18: =L18/L9 -> 0.019939941
B19: 4:17-4:22辊印更换F3工作辊！ | H19: 5 | I19: =ROUND(H19/60,1) -> 0.1 | J19: 合计（m³） | L19: =L18+'07-05-26'!L19:M19 -> 67 | N19: 合计吨钢消耗 （m³/t） | O19: =L19/L10 -> 0.019877778
J20: 原料打包带(น้ำหนักสายรัดวัตถุ) PK | N20: 焊接切除废料(เศษวัสดุหลังการเชื่อม)PK
B21: 6:15-6:21调试自动焊机！ | H21: 6 | I21: =ROUND(H21/60,1) -> 0.1 | J21: 当日（kg） | L21: 330 | N21: 当日（kg） | O21: 430
J22: 合计（kg） | L22: =L21+'07-05-26'!L22:M22 -> 2450 | N22: 合计（kg） | O22: =O21+'07-05-26'!O22 -> 2790
J23: 切头切尾 (scapหัว-ท้าย) | N23: 工艺段及活套废料 (เศษวัสดุจากกระบวนการผลิต)
J24: 当日（kg） | L24: 230 | N24: 当日（kg）
J25: 合计（kg） | L25: =L24+'07-05-26'!L25:M25 -> 1381 | N25: 合计（kg）
J26: 酸洗天然气( แก๊ส PK)
J27: 当日（Nm3） | L27: 1525 | N27: 当日吨钢消耗 （Nm3/t） | O27: =L27/L9 -> 3.040841
J28: 合计（Nm3） | L28: =L27+'07-05-26'!L28:M28 -> 10754 | N28: 合计吨钢消耗 （Nm3/t） | O28: =L28/L10 -> 3.1905318
J29: 缓蚀剂 (Actived 1803 )
J30: 当日（L） | L30: 30
J31: 合计(L) | L31: =L30+'07-05-26'!L31:O31 -> 201
J32: 轧机电耗 (ไฟฟ้า) CRL
I33: =ROUND(I16+I17+I19+I22+I23+I25+I27+I29+I31,1) -> 0.3 | J33: 当日（kwh） | L33: 19692 | N33: 当日吨钢消耗 （kwh/t） | O33: =L33/O9 -> 39.575227
J34: 合计（kwh） | L34: =L33+'07-05-26'!L34:M34 -> 139630 | N34: 合计吨钢消耗 （kwh/t） | O34: =L34/O10 -> 41.7911
A35: 质量概述 QC | B35: B级品：1卷原料边裂！ | J35: 轧机废料 (เศษวัสดุจากเครื่องรีด) | N35: 成材率 (อัตราการผลิต)
J36: 断带废ของเสียจากสายพานขาด（kg） | L36: 0 | M36: =L36+'07-05-26'!M36 -> 1489 | N36: =L36/1000/L9 -> 0 | O36: =M36/1000/L10 -> 0.00044176137
J37: 调整废（kg）ของเสียจากการปรับตั้ง | L37: 102 | M37: =L37+'07-05-26'!M37 -> 1427 | N37: =L37/1000/L9 -> 0.0002033874 | O37: =M37/1000/L10 -> 0.00042336701
J38: 孔洞、边裂（kg）ของเสียจากขอบแตก | L38: 158 | M38: =L38+'07-05-26'!M38 -> 1515 | N38: =L38/1000/L9 -> 0.00031505107 | O38: =M38/1000/L10 -> 0.00044947514
J39: 当日（kg） | L39: =L36+L37+L38 -> 260 | N39: 当日（%） | O39: =O9/L9 -> 0.99217956
J40: 合计（kg） | L40: =L39+'07-05-26'!L40:M40 -> 4431 | N40: 合计（%） | O40: =(O10)/(L10-L22/1000) -> 0.99198194
J41: 轧制油 (Coolant)
...

Sheet 09-05-26
A1: 酸轧线生产运行记录总表 สรุปการผลิต PK CRL Line
M2: 日期 (Date)
A3: 生产数据记录 บันทึกข้อมูลการผลิต | B3: 序号 Item | C3: 生产订单 Production Order | D3: 原料规格 size of material | E3: 原料重量 Weight of material（t） | F3: 原料卷数PK（coil） | G3: 成品规格 Description product | H3: 成品重量 weight of product (t) | I3: 成品卷数 CRL（coil） | J3: 各项指标及能源消耗 (ตัวชี้วัดและการใช้พลังงาน)
B5: 1 | C5: 138100000546 | D5: HRC 3.00 x 434 SPHC | E5: 173182 | F5: 33 | G5: CRC 1.30 x 434 SPCC | H5: 171794 | I5: 33 | J5: B级品 (เกรด B) | N5: 一级品率 (เกรด A)
B6: 2 | C6: 138100000545 | D6: HRC 4.00 x 434 SPHC | E6: 26265 | F6: 5 | G6: CRC 1.30 x 434 SPCC | H6: 26030 | I6: 5 | J6: 当日 /วัน（T） | L6: 5.114 | N6: 当日/ วัน（%） | O6: =(O9-L6)/O9 -> 0.99020858
B7: 3 | C7: 138100000547 | D7: HRC 3.50 x 433 SPHC | E7: 52600 | F7: 10 | G7: CRC 1.30 x 433 SPCC | H7: 52212 | I7: 10 | J7: 合计/ทั้งหมด（T） | L7: =L6+'08-05-26'!L7:M7 -> 126.63 | N7: 合计/ ทั้งหมด（%） | O7: =(O10-L7)/O10 -> 0.96722348
B8: 4 | C8: 138100000562 | D8: HRC 3.50 x 478 SPHC | E8: 114131 | F8: 20 | G8: CRC 1.30 x 478 SPCC | H8: 113068 | I8: 20 | J8: 原料重量 (น้ำหนักวัตถุดิบ) PK | N8: 成品重量 (น้ำหนักวัตถุดิบ) CRL
B9: 5 | C9: 138100000563 | D9: HRC 4.00 x 478 SPHC | E9: 5750 | F9: 1 | G9: CRC 1.30 x 478 SPCC | H9: 5710 | I9: 1 | J9: 当日（t） | L9: 526.704 | N9: 当日（t） | O9: 522.294
B10: 6 | C10: 138100000575 | D10: HRC 4.00 x 475 SPHC | E10: 103182 | F10: 18 | G10: CRC 1.30 x 475 SPCC | H10: 102356 | I10: 18 | J10: 合计（t） | L10: =L9+'08-05-26'!L10:M10 -> 3897.302 | N10: 合计（t） | O10: =O9+'08-05-26'!O10 -> 3863.436
B11: 7 | C11: 138100000573 | D11: HRC 3.00 x 437 SPHC | E11: 5239 | F11: 1 | G11: CRC 1.30 x 437 SPCC | H11: 5158 | I11: 1 | J11: 机时产量(อัตราการผลิต/1ชั่วโมง) | N11: 有效作业率 (อัตราการทำงาน)
B12: 8 | C12: 138100000549 | D12: HRC 2.22 x 426 SPHC | E12: 46355 | F12: 9 | G12: CRC 1.11 x 426 SPCC | H12: 45966 | I12: 9 | J12: 当日（t/h） | L12: =O9/(11-I33) -> 49.742286 | N12: 当日 （%） | O12: =(11-I33)/11 -> 0.95454545
J13: 合计（t/h） | L13: =O10/O46 -> 47.057686 | N13: 合计（%） | O13: =O46/L46 -> 0.93295455
J14: 酸洗电耗 ( ไฟฟ้า) PK
A15: 停机记录 บันทึกการหยุดเครื่อง | B15: 22:54-22:59辊印更换F2工作辊！ | H15: 分钟 | I15: 小时 | J15: 当日（kwh） | L15: 3407 | N15: 当日吨钢消耗 （kwh/t） | O15: =L15/L9 -> 6.4685288
H16: 5 | I16: =ROUND(H16/60,1) -> 0.1 | J16: 合计（kwh） | L16: =L15+'08-05-26'!L16:M16 -> 26076 | N16: 合计吨钢消耗 （kwh/t） | O16: =L16/L10 -> 6.6907825
B17: 23:33-23:40自动焊机调试！ | H17: 7 | I17: =ROUND(H17/60,1) -> 0.1 | J17: 盐酸 (HCL)
J18: 当日（m³） | L18: 10 | N18: 当日吨钢消耗 （m³/t） | O18: =L18/L9 -> 0.018985996
B19: 3:07-3:17窄带改宽带更换F1.2.3工作辊！ | H19: 10 | I19: =ROUND(H19/60,1) -> 0.2 | J19: 合计（m³） | L19: =L18+'08-05-26'!L19:M19 -> 77 | N19: 合计吨钢消耗 （m³/t） | O19: =L19/L10 -> 0.019757258
J20: 原料打包带(น้ำหนักสายรัดวัตถุ) PK | N20: 焊接切除废料(เศษวัสดุหลังการเชื่อม)PK
B21: 3:22-3:29窄带改宽带更换F4工作辊！ | H21: 7 | I21: =ROUND(H21/60,1) -> 0.1 | J21: 当日（kg） | L21: 350 | N21: 当日（kg） | O21: 422
J22: 合计（kg） | L22: =L21+'08-05-26'!L22:M22 -> 2800 | N22: 合计（kg） | O22: =O21+'08-05-26'!O22 -> 3212
B23: 6:52-7:00自动焊机调试！ | H23: 8 | I23: =ROUND(H23/60,1) -> 0.1 | J23: 切头切尾 (scapหัว-ท้าย) | N23: 工艺段及活套废料 (เศษวัสดุจากกระบวนการผลิต)
J24: 当日（kg） | L24: 198 | N24: 当日（kg）
J25: 合计（kg） | L25: =L24+'08-05-26'!L25:M25 -> 1579 | N25: 合计（kg）
J26: 酸洗天然气( แก๊ส PK)
J27: 当日（Nm3） | L27: 1415 | N27: 当日吨钢消耗 （Nm3/t） | O27: =L27/L9 -> 2.6865184
J28: 合计（Nm3） | L28: =L27+'08-05-26'!L28:M28 -> 12169 | N28: 合计吨钢消耗 （Nm3/t） | O28: =L28/L10 -> 3.1224165
J29: 缓蚀剂 (Actived 1803 )
J30: 当日（L） | L30: 30
J31: 合计(L) | L31: =L30+'08-05-26'!L31:O31 -> 231
J32: 轧机电耗 (ไฟฟ้า) CRL
I33: =ROUND(I16+I17+I19+I22+I23+I25+I27+I29+I31,1) -> 0.5 | J33: 当日（kwh） | L33: 22088 | N33: 当日吨钢消耗 （kwh/t） | O33: =L33/O9 -> 42.290358
J34: 合计（kwh） | L34: =L33+'08-05-26'!L34:M34 -> 161718 | N34: 合计吨钢消耗 （kwh/t） | O34: =L34/O10 -> 41.858594
A35: 质量概述 QC | B35: B级品：1卷原料边裂！ | J35: 轧机废料 (เศษวัสดุจากเครื่องรีด) | N35: 成材率 (อัตราการผลิต)
J36: 断带废ของเสียจากสายพานขาด（kg） | L36: 96 | M36: =L36+'08-05-26'!M36 -> 1585 | N36: =L36/1000/L9 -> 0.00018226556 | O36: =M36/1000/L10 -> 0.0004066916
J37: 调整废（kg）ของเสียจากการปรับตั้ง | L37: 210 | M37: =L37+'08-05-26'!M37 -> 1637 | N37: =L37/1000/L9 -> 0.00039870591 | O37: =M37/1000/L10 -> 0.00042003417
J38: 孔洞、边裂（kg）ของเสียจากขอบแตก | L38: 170 | M38: =L38+'08-05-26'!M38 -> 1685 | N38: =L38/1000/L9 -> 0.00032276193 | O38: =M38/1000/L10 -> 0.00043235038
J39: 当日（kg） | L39: =L36+L37+L38 -> 476 | N39: 当日（%） | O39: =O9/L9 -> 0.99162718
J40: 合计（kg） | L40: =L39+'08-05-26'!L40:M40 -> 4907 | N40: 合计（%） | O40: =(O10)/(L10-L22/1000) -> 0.99202311
J41: 轧制油 (Coolant)
...

Sheet 10-05-26 
A1: 酸轧线生产运行记录总表 สรุปการผลิต PK CRL Line
M2: 日期 (Date)
A3: 生产数据记录 บันทึกข้อมูลการผลิต | B3: 序号 Item | C3: 生产订单 Production Order | D3: 原料规格 size of material | E3: 原料重量 Weight of material（t） | F3: 原料卷数PK（coil） | G3: 成品规格 Description product | H3: 成品重量 weight of product (t) | I3: 成品卷数 CRL（coil） | J3: 各项指标及能源消耗 (ตัวชี้วัดและการใช้พลังงาน)
B5: 1 | C5: 138100000549 | D5: HRC 2.22 x 426 SPHC | E5: 305884 | F5: 60 | G5: CRC 1.11 x 426 SPCC | H5: 302912 | I5: 60 | J5: B级品 (เกรด B) | N5: 一级品率 (เกรด A)
B6: 2 | C6: 138100000519 | D6: HRC 3.00 x 389 SPHC | E6: 4718 | F6: 1 | G6: CRC 1.11 x 388 SPCC | H6: 4522 | I6: 1 | J6: 当日 /วัน（T） | L6: 19.258 | N6: 当日/ วัน（%） | O6: =(O9-L6)/O9 -> 0.95167911
B7: 3 | C7: 138100000574 | D7: HRC 3.50 x 388 SPHC | E7: 27623 | F7: 6 | G7: CRC 1.11 x 388 SPCC | H7: 27346 | I7: 6 | J7: 合计/ทั้งหมด（T） | L7: =L6+'09-05-26'!L7:M7 -> 145.888 | N7: 合计/ ทั้งหมด（%） | O7: =(O10-L7)/O10 -> 0.9657699
B8: 4 | C8: 138100000521 | D8: HRC 3.50 x 388 SPHC | E8: 64337 | F8: 14 | G8: CRC 1.30 x 388 SPCC | H8: 63764 | I8: 14 | J8: 原料重量 (น้ำหนักวัตถุดิบ) PK | N8: 成品重量 (น้ำหนักวัตถุดิบ) CRL
J9: 当日（t） | L9: 402.562 | N9: 当日（t） | O9: 398.544
J10: 合计（t） | L10: =L9+'09-05-26'!L10:M10 -> 4299.864 | N10: 合计（t） | O10: =O9+'09-05-26'!O10 -> 4261.98
J11: 机时产量(อัตราการผลิต/1ชั่วโมง) | N11: 有效作业率 (อัตราการทำงาน)
J12: 当日（t/h） | L12: =O9/(11-I33) -> 38.321538 | N12: 当日 （%） | O12: =(11-I33)/11 -> 0.94545455
J13: 合计（t/h） | L13: =O10/O46 -> 46.075459 | N13: 合计（%） | O13: =O46/L46 -> 0.93434343
J14: 酸洗电耗 ( ไฟฟ้า) PK
A15: 停机记录 บันทึกการหยุดเครื่อง | B15: 23:17-23:29焊接头开裂！ | H15: 分钟 | I15: 小时 | J15: 当日（kwh） | L15: 3265 | N15: 当日吨钢消耗 （kwh/t） | O15: =L15/L9 -> 8.1105519
H16: 12 | I16: =ROUND(H16/60,1) -> 0.2 | J16: 合计（kwh） | L16: =L15+'09-05-26'!L16:M16 -> 29341 | N16: 合计吨钢消耗 （kwh/t） | O16: =L16/L10 -> 6.8237042
B17: 23:35-23:41辊印更换F4工作辊！ | H17: 6 | I17: =ROUND(H17/60,1) -> 0.1 | J17: 盐酸 (HCL)
J18: 当日（m³） | L18: 9 | N18: 当日吨钢消耗 （m³/t） | O18: =L18/L9 -> 0.022356805
B19: 0:51-0:57自动焊机调试！ | H19: 6 | I19: =ROUND(H19/60,1) -> 0.1 | J19: 合计（m³） | L19: =L18+'09-05-26'!L19:M19 -> 86 | N19: 合计吨钢消耗 （m³/t） | O19: =L19/L10 -> 0.020000633
J20: 原料打包带(น้ำหนักสายรัดวัตถุ) PK | N20: 焊接切除废料(เศษวัสดุหลังการเชื่อม)PK
B21: 5:32-5:44轧制426*2.22原料时由于前期停机料二次酸洗，原料薄1.8导致F1入口断带！ | H21: 12 | I21: =ROUND(H21/60,1) -> 0.2 | J21: 当日（kg） | L21: 288 | N21: 当日（kg） | O21: 270
J22: 合计（kg） | L22: =L21+'09-05-26'!L22:M22 -> 3088 | N22: 合计（kg） | O22: =O21+'09-05-26'!O22 -> 3482
B23: 6:28-6:39改料带尾裂口断F2出口，更换F3工作辊！ | H23: 11 | I23: =ROUND(H23/60,1) -> 0.2 | J23: 切头切尾 (scapหัว-ท้าย) | N23: 工艺段及活套废料 (เศษวัสดุจากกระบวนการผลิต)
J24: 当日（kg） | L24: 120 | N24: 当日（kg）
J25: 合计（kg） | L25: =L24+'09-05-26'!L25:M25 -> 1699 | N25: 合计（kg）
J26: 酸洗天然气( แก๊ส PK)
J27: 当日（Nm3） | L27: 1372 | N27: 当日吨钢消耗 （Nm3/t） | O27: =L27/L9 -> 3.4081707
J28: 合计（Nm3） | L28: =L27+'09-05-26'!L28:M28 -> 13541 | N28: 合计吨钢消耗 （Nm3/t） | O28: =L28/L10 -> 3.1491694
J29: 缓蚀剂 (Actived 1803 )
J30: 当日（L） | L30: 27
J31: 合计(L) | L31: =L30+'09-05-26'!L31:O31 -> 258
J32: 轧机电耗 (ไฟฟ้า) CRL
I33: =ROUND(I16+I17+I19+I22+I23+I25+I27+I29+I31,1) -> 0.6 | J33: 当日（kwh） | L33: 16870 | N33: 当日吨钢消耗 （kwh/t） | O33: =L33/O9 -> 42.329078
J34: 合计（kwh） | L34: =L33+'09-05-26'!L34:M34 -> 178588 | N34: 合计吨钢消耗 （kwh/t） | O34: =L34/O10 -> 41.90259
A35: 质量概述 QC | B35: B级品：6卷，4个小卷，2个大卷！ | J35: 轧机废料 (เศษวัสดุจากเครื่องรีด) | N35: 成材率 (อัตราการผลิต)
J36: 断带废ของเสียจากสายพานขาด（kg） | L36: 330 | M36: =L36+'09-05-26'!M36 -> 1915 | N36: =L36/1000/L9 -> 0.0008197495 | O36: =M36/1000/L10 -> 0.00044536292
J37: 调整废（kg）ของเสียจากการปรับตั้ง | L37: 185 | M37: =L37+'09-05-26'!M37 -> 1822 | N37: =L37/1000/L9 -> 0.00045955654 | O37: =M37/1000/L10 -> 0.00042373433
J38: 孔洞、边裂（kg）ของเสียจากขอบแตก | L38: 369 | M38: =L38+'09-05-26'!M38 -> 2054 | N38: =L38/1000/L9 -> 0.00091662899 | O38: =M38/1000/L10 -> 0.00047768953
J39: 当日（kg） | L39: =L36+L37+L38 -> 884 | N39: 当日（%） | O39: =O9/L9 -> 0.99001893
J40: 合计（kg） | L40: =L39+'09-05-26'!L40:M40 -> 5791 | N40: 合计（%） | O40: =(O10)/(L10-L22/1000) -> 0.99190184
J41: 轧制油 (Coolant)
...

Sheet 11-05-26
A1: 酸轧线生产运行记录总表 สรุปการผลิต PK CRL Line
M2: 日期 (Date)
A3: 生产数据记录 บันทึกข้อมูลการผลิต | B3: 序号 Item | C3: 生产订单 Production Order | D3: 原料规格 size of material | E3: 原料重量 Weight of material（t） | F3: 原料卷数PK（coil） | G3: 成品规格 Description product | H3: 成品重量 weight of product (t) | I3: 成品卷数 CRL（coil） | J3: 各项指标及能源消耗 (ตัวชี้วัดและการใช้พลังงาน)
B5: 1 | C5: 138100000521 | D5: HRC 3.50 x 388 SPHC | E5: 137672 | F5: 30 | G5: CRC 1.30 x 388 SPCC | H5: 136728 | I5: 30 | J5: B级品 (เกรด B) | N5: 一级品率 (เกรด A)
B6: 2 | C6: 138100000567 | D6: HRC 4.00 x 388 SS400 | E6: 31111 | F6: 7 | G6: CRC 1.30 x 388 SPCC | H6: 30374 | I6: 7 | J6: 当日 /วัน（T） | L6: 4.364 | N6: 当日/ วัน（%） | O6: =(O9-L6)/O9 -> 0.99111838
B7: 3 | C7: 138100000564 | D7: HRC 4.00 x 390 SPHC | E7: 36794 | F7: 8 | G7: CRC 1.30 x 390 SPCC | H7: 36446 | I7: 8 | J7: 合计/ทั้งหมด（T） | L7: =L6+'10-05-26 '!L7:M7 -> 150.252 | N7: 合计/ ทั้งหมด（%） | O7: =(O10-L7)/O10 -> 0.96839017
B8: 4 | C8: 138100000569 | D8: HRC 3.50 x 387 SPHC | E8: 63152 | F8: 14 | G8: CRC 1.30 x 387 SPCC | H8: 62616 | I8: 14 | J8: 原料重量 (น้ำหนักวัตถุดิบ) PK | N8: 成品重量 (น้ำหนักวัตถุดิบ) CRL
B9: 5 | C9: 138100000570 | D9: HRC 3.50 x 435 SPHC | E9: 84359 | F9: 16 | G9: CRC 1.11 x 435 SPCC | H9: 83686 | I9: 16 | J9: 当日（t） | L9: 495.699 | N9: 当日（t） | O9: 491.352
B10: 6 | C10: 138100000535 | D10: HRC 3.50 x 435 SPHC | E10: 142611 | F10: 27 | G10: CRC 1.48 x 435 SPCC | H10: 141502 | I10: 27 | J10: 合计（t） | L10: =L9+'10-05-26 '!L10:M10 -> 4795.563 | N10: 合计（t） | O10: =O9+'10-05-26 '!O10 -> 4753.332
J11: 机时产量(อัตราการผลิต/1ชั่วโมง) | N11: 有效作业率 (อัตราการทำงาน)
J12: 当日（t/h） | L12: =O9/(11-I33) -> 47.704078 | N12: 当日 （%） | O12: =(11-I33)/11 -> 0.93636364
J13: 合计（t/h） | L13: =O10/O46 -> 46.238638 | N13: 合计（%） | O13: =O46/L46 -> 0.93454545
J14: 酸洗电耗 ( ไฟฟ้า) PK
A15: 停机记录 บันทึกการหยุดเครื่อง | B15: 1:12-1:28辊印更换F1F2工作辊！ | H15: 分钟 | I15: 小时 | J15: 当日（kwh） | L15: 3543 | N15: 当日吨钢消耗 （kwh/t） | O15: =L15/L9 -> 7.1474826
H16: 16 | I16: =ROUND(H16/60,1) -> 0.3 | J16: 合计（kwh） | L16: =L15+'10-05-26 '!L16:M16 -> 32884 | N16: 合计吨钢消耗 （kwh/t） | O16: =L16/L10 -> 6.8571719
B17: 2:06-2:12辊印更换F4工作辊！ | H17: 6 | I17: =ROUND(H17/60,1) -> 0.1 | J17: 盐酸 (HCL)
J18: 当日（m³） | L18: 9 | N18: 当日吨钢消耗 （m³/t） | O18: =L18/L9 -> 0.018156179
B19: 4:10-4:28窄带改宽带换F1F2F3F4工作辊！ | H19: 18 | I19: =ROUND(H19/60,1) -> 0.3 | J19: 合计（m³） | L19: =L18+'10-05-26 '!L19:M19 -> 95 | N19: 合计吨钢消耗 （m³/t） | O19: =L19/L10 -> 0.019809979
J20: 原料打包带(น้ำหนักสายรัดวัตถุ) PK | N20: 焊接切除废料(เศษวัสดุหลังการเชื่อม)PK
B21: 6:39-6:43自动焊机调试！ | H21: 4 | I21: =ROUND(H21/60,1) -> 0.1 | J21: 当日（kg） | L21: 398 | N21: 当日（kg） | O21: 234
J22: 合计（kg） | L22: =L21+'10-05-26 '!L22:M22 -> 3486 | N22: 合计（kg） | O22: =O21+'10-05-26 '!O22 -> 3716
J23: 切头切尾 (scapหัว-ท้าย) | N23: 工艺段及活套废料 (เศษวัสดุจากกระบวนการผลิต)
J24: 当日（kg） | L24: 234 | N24: 当日（kg）
J25: 合计（kg） | L25: =L24+'09-05-26'!L25:M25 -> 1813 | N25: 合计（kg）
J26: 酸洗天然气( แก๊ส PK)
J27: 当日（Nm3） | L27: 1295 | N27: 当日吨钢消耗 （Nm3/t） | O27: =L27/L9 -> 2.6124725
J28: 合计（Nm3） | L28: =L27+'10-05-26 '!L28:M28 -> 14836 | N28: 合计吨钢消耗 （Nm3/t） | O28: =L28/L10 -> 3.0936931
J29: 缓蚀剂 (Actived 1803 )
J30: 当日（L） | L30: 27
J31: 合计(L) | L31: =L30+'10-05-26 '!L31:O31 -> 285
J32: 轧机电耗 (ไฟฟ้า) CRL
I33: =ROUND(I16+I17+I19+I22+I23+I25+I27+I29+I31,1) -> 0.7 | J33: 当日（kwh） | L33: 22232 | N33: 当日吨钢消耗 （kwh/t） | O33: =L33/O9 -> 45.246585
J34: 合计（kwh） | L34: =L33+'10-05-26 '!L34:M34 -> 200820 | N34: 合计吨钢消耗 （kwh/t） | O34: =L34/O10 -> 42.248259
A35: 质量概述 QC | B35: B级品：原料边裂1卷 | J35: 轧机废料 (เศษวัสดุจากเครื่องรีด) | N35: 成材率 (อัตราการผลิต)
J36: 断带废ของเสียจากสายพานขาด（kg） | L36: 108 | M36: =L36+'10-05-26 '!M36 -> 2023 | N36: =L36/1000/L9 -> 0.00021787415 | O36: =M36/1000/L10 -> 0.00042184828
J37: 调整废（kg）ของเสียจากการปรับตั้ง | L37: 356 | M37: =L37+'10-05-26 '!M37 -> 2178 | N37: =L37/1000/L9 -> 0.00071817777 | O37: =M37/1000/L10 -> 0.00045416982
J38: 孔洞、边裂（kg）ของเสียจากขอบแตก | L38: 330 | M38: =L38+'10-05-26 '!M38 -> 2384 | N38: =L38/1000/L9 -> 0.00066572658 | O38: =M38/1000/L10 -> 0.0004971262
J39: 当日（kg） | L39: =L36+L37+L38 -> 794 | N39: 当日（%） | O39: =O9/L9 -> 0.99123057
J40: 合计（kg） | L40: =L39+'10-05-26 '!L40:M40 -> 6585 | N40: 合计（%） | O40: =(O10)/(L10-L22/1000) -> 0.99191478
J41: 轧制油 (Coolant)
...

Sheet 12-05-26 
A1: 酸轧线生产运行记录总表 สรุปการผลิต PK CRL Line
M2: 日期 (Date)
A3: 生产数据记录 บันทึกข้อมูลการผลิต | B3: 序号 Item | C3: 生产订单 Production Order | D3: 原料规格 size of material | E3: 原料重量 Weight of material（t） | F3: 原料卷数PK（coil） | G3: 成品规格 Description product | H3: 成品重量 weight of product (t) | I3: 成品卷数 CRL（coil） | J3: 各项指标及能源消耗 (ตัวชี้วัดและการใช้พลังงาน)
B5: 1 | C5: 138100000535 | D5: HRC 3.50 x 435 SPHC | E5: 58002 | F5: 11 | G5: CRC 1.48 x 435 SPCC | H5: 57540 | I5: 11 | J5: B级品 (เกรด B) | N5: 一级品率 (เกรด A)
B6: 2 | C6: 138100000560 | D6: HRC 3.50 x 422 SPHC | E6: 5184 | F6: 1 | G6: CRC 1.48 x 422 SPCC | H6: 4906 | I6: 1 | J6: 当日 /วัน（T） | L6: 0 | N6: 当日/ วัน（%） | O6: =(O9-L6)/O9 -> 1
B7: 3 | C7: 138100000565 | D7: HRC 4.20 x 476 SPHC | E7: 5730 | F7: 1 | G7: CRC 1.84 x 472 SPCC | H7: 5662 | I7: 1 | J7: 合计/ทั้งหมด（T） | L7: =L6+'11-05-26'!L7:M7 -> 150.252 | N7: 合计/ ทั้งหมด（%） | O7: =(O10-L7)/O10 -> 0.97156097
B8: 4 | C8: 138100000566 | D8: HRC 4.50 x 472 SPHC | E8: 113298 | F8: 20 | G8: CRC 1.84 x 472 SPCC | H8: 112426 | I8: 20 | J8: 原料重量 (น้ำหนักวัตถุดิบ) PK | N8: 成品重量 (น้ำหนักวัตถุดิบ) CRL
B9: 5 | C9: 138100000552 | D9: HRC 4.50 x 457 SPHC | E9: 102987 | F9: 19 | G9: CRC 2.10 x 457 SPCC | H9: 101650 | I9: 19 | J9: 当日（t） | L9: 534.934 | N9: 当日（t） | O9: 529.97
B10: 6 | C10: 138100000553 | D10: HRC 4.50 x 443 SPHC | E10: 89275 | F10: 17 | G10: CRC 2.10 x 443 SPCC | H10: 88580 | I10: 17 | J10: 合计（t） | L10: =L9+'11-05-26'!L10:M10 -> 5330.497 | N10: 合计（t） | O10: =O9+'11-05-26'!O10 -> 5283.302
B11: 7 | C11: 138100000572 | D11: HRC 4.50 x 422 SPHC | E11: 160458 | F11: 32 | G11: CRC 1.84 x 422 SPCC | H11: 159206 | I11: 32 | J11: 机时产量(อัตราการผลิต/1ชั่วโมง) | N11: 有效作业率 (อัตราการทำงาน)
J12: 当日（t/h） | L12: =O9/(11-I33) -> 52.997 | N12: 当日 （%） | O12: =(11-I33)/11 -> 0.90909091
J13: 合计（t/h） | L13: =O10/O46 -> 46.837784 | N13: 合计（%） | O13: =O46/L46 -> 0.9322314
J14: 酸洗电耗 ( ไฟฟ้า) PK
A15: 停机记录 บันทึกการหยุดเครื่อง | B15: 23:00-23:20窄带改宽带换F1.F2.F3.F4工作辊！ | H15: 分钟 | I15: 小时 | J15: 当日（kwh） | L15: 3717 | N15: 当日吨钢消耗 （kwh/t） | O15: =L15/L9 -> 6.9485208
H16: 20 | I16: =ROUND(H16/60,1) -> 0.3 | J16: 合计（kwh） | L16: =L15+'11-05-26'!L16:M16 -> 36601 | N16: 合计吨钢消耗 （kwh/t） | O16: =L16/L10 -> 6.8663391
B17: 0:13-0:19自动焊机调试！ | H17: 6 | I17: =ROUND(H17/60,1) -> 0.1 | J17: 盐酸 (HCL)
J18: 当日（m³） | L18: 10 | N18: 当日吨钢消耗 （m³/t） | O18: =L18/L9 -> 0.018693895
B19: 2:40-3:05原料镰刀弯F1入口断带！ | H19: 25 | I19: =ROUND(H19/60,1) -> 0.4 | J19: 合计（m³） | L19: =L18+'11-05-26'!L19:M19 -> 105 | N19: 合计吨钢消耗 （m³/t） | O19: =L19/L10 -> 0.019697976
J20: 原料打包带(น้ำหนักสายรัดวัตถุ) PK | N20: 焊接切除废料(เศษวัสดุหลังการเชื่อม)PK
B21: 3:12-3:27原料镰刀弯F1出口断带！ | H21: 15 | I21: =ROUND(H21/60,1) -> 0.3 | J21: 当日（kg） | L21: 354 | N21: 当日（kg） | O21: 520
J22: 合计（kg） | L22: =L21+'11-05-26'!L22:M22 -> 3840 | N22: 合计（kg） | O22: =O21+'11-05-26'!O22 -> 4236
B23: 3:37-3:45辊印更换F1.F3工作辊！ | H23: 8 | I23: =ROUND(H23/60,1) -> 0.1 | J23: 切头切尾 (scapหัว-ท้าย) | N23: 工艺段及活套废料 (เศษวัสดุจากกระบวนการผลิต)
J24: 当日（kg） | L24: 322 | N24: 当日（kg）
B25: 5:55-6:00自动焊机二次焊机！ | H25: 5 | I25: =ROUND(H25/60,1) -> 0.1 | J25: 合计（kg） | L25: =L24+'11-05-26'!L25:M25 -> 2135 | N25: 合计（kg）
J26: 酸洗天然气( แก๊ส PK)
J27: 当日（Nm3） | L27: 1369 | N27: 当日吨钢消耗 （Nm3/t） | O27: =L27/L9 -> 2.5591942
J28: 合计（Nm3） | L28: =L27+'11-05-26'!L28:M28 -> 16205 | N28: 合计吨钢消耗 （Nm3/t） | O28: =L28/L10 -> 3.0400542
J29: 缓蚀剂 (Actived 1803 )
J30: 当日（L） | L30: 30
J31: 合计(L) | L31: =L30+'11-05-26'!L31:O31 -> 315
J32: 轧机电耗 (ไฟฟ้า) CRL
I33: =ROUND(I16+I17+I19+I22+I23+I25+I27+I29+I31,1) -> 1 | J33: 当日（kwh） | L33: 20494 | N33: 当日吨钢消耗 （kwh/t） | O33: =L33/O9 -> 38.670113
J34: 合计（kwh） | L34: =L33+'11-05-26'!L34:M34 -> 221314 | N34: 合计吨钢消耗 （kwh/t） | O34: =L34/O10 -> 41.889334
A35: 质量概述 QC | J35: 轧机废料 (เศษวัสดุจากเครื่องรีด) | N35: 成材率 (อัตราการผลิต)
J36: 断带废ของเสียจากสายพานขาด（kg） | L36: 102 | M36: =L36+'11-05-26'!M36 -> 2125 | N36: =L36/1000/L9 -> 0.00019067773 | O36: =M36/1000/L10 -> 0.00039864951
J37: 调整废（kg）ของเสียจากการปรับตั้ง | L37: 142 | M37: =L37+'11-05-26'!M37 -> 2320 | N37: =L37/1000/L9 -> 0.00026545331 | O37: =M37/1000/L10 -> 0.00043523146
J38: 孔洞、边裂（kg）ของเสียจากขอบแตก | L38: 245 | M38: =L38+'11-05-26'!M38 -> 2629 | N38: =L38/1000/L9 -> 0.00045800043 | O38: =M38/1000/L10 -> 0.00049319979
J39: 当日（kg） | L39: =L36+L37+L38 -> 489 | N39: 当日（%） | O39: =O9/L9 -> 0.99072035
J40: 合计（kg） | L40: =L39+'11-05-26'!L40:M40 -> 7074 | N40: 合计（%） | O40: =(O10)/(L10-L22/1000) -> 0.99186075
J41: 轧制油 (Coolant)
...

Sheet 13-05-26
A1: 酸轧线生产运行记录总表 สรุปการผลิต PK CRL Line
M2: 日期 (Date)
A3: 生产数据记录 บันทึกข้อมูลการผลิต | B3: 序号 Item | C3: 生产订单 Production Order | D3: 原料规格 size of material | E3: 原料重量 Weight of material（t） | F3: 原料卷数PK（coil） | G3: 成品规格 Description product | H3: 成品重量 weight of product (t) | I3: 成品卷数 CRL（coil） | J3: 各项指标及能源消耗 (ตัวชี้วัดและการใช้พลังงาน)
B5: 1 | C5: 138100000572 | D5: HRC 4.50 x 422 SPHC | E5: 135784 | F5: 27 | G5: CRC 1.84 x 422 SPCC | H5: 134762 | I5: 27 | J5: B级品 (เกรด B) | N5: 一级品率 (เกรด A)
B6: 2 | C6: 138100000554 | D6: HRC 4.00 x 415 SPHC | E6: 9905 | F6: 2 | G6: CRC 1.84 x 412 SPCC | H6: 9818 | I6: 2 | J6: 当日 /วัน（T） | L6: 14.112 | N6: 当日/ วัน（%） | O6: =(O9-L6)/O9 -> 0.97187422
B7: 3 | C7: 138100000555 | D7: HRC 3.50 x 412 SPHC | E7: 159168 | F7: 33 | G7: CRC 1.84 x 412 SPCC | H7: 158032 | I7: 33 | J7: 合计/ทั้งหมด（T） | L7: =L6+'12-05-26 '!L7:M7 -> 164.364 | N7: 合计/ ทั้งหมด（%） | O7: =(O10-L7)/O10 -> 0.97158814
B8: 4 | C8: 138100000523 | D8: HRC 4.20 x 389 SPHC | E8: 91185 | F8: 20 | G8: CRC 1.84 x 389 SPCC | H8: 90104 | I8: 20 | J8: 原料重量 (น้ำหนักวัตถุดิบ) PK | N8: 成品重量 (น้ำหนักวัตถุดิบ) CRL
B9: 5 | C9: 138100000524 | D9: HRC 4.50 x 389 SPHC | E9: 110114 | F9: 24 | G9: CRC 1.84 x 389 SPCC | H9: 109030 | I9: 24 | J9: 当日（t） | L9: 506.156 | N9: 当日（t） | O9: 501.746
J10: 合计（t） | L10: =L9+'12-05-26 '!L10:M10 -> 5836.653 | N10: 合计（t） | O10: =O9+'12-05-26 '!O10 -> 5785.048
J11: 机时产量(อัตราการผลิต/1ชั่วโมง) | N11: 有效作业率 (อัตราการทำงาน)
J12: 当日（t/h） | L12: =O9/(11-I33) -> 47.785333 | N12: 当日 （%） | O12: =(11-I33)/11 -> 0.95454545
J13: 合计（t/h） | L13: =O10/O46 -> 46.918475 | N13: 合计（%） | O13: =O46/L46 -> 0.93409091
J14: 酸洗电耗 ( ไฟฟ้า) PK
A15: 停机记录 บันทึกการหยุดเครื่อง | B15: 23:35-23:42原料版型不好，二次焊接！ | H15: 分钟 | I15: 小时 | J15: 当日（kwh） | L15: 3514 | N15: 当日吨钢消耗 （kwh/t） | O15: =L15/L9 -> 6.9425236
H16: 7 | I16: =ROUND(H16/60,1) -> 0.1 | J16: 合计（kwh） | L16: =L15+'12-05-26 '!L16:M16 -> 40115 | N16: 合计吨钢消耗 （kwh/t） | O16: =L16/L10 -> 6.8729458
B17: 4:21-4:39辊印更换F4.F1工作辊！ | H17: 18 | I17: =ROUND(H17/60,1) -> 0.3 | J17: 盐酸 (HCL)
J18: 当日（m³） | L18: 9 | N18: 当日吨钢消耗 （m³/t） | O18: =L18/L9 -> 0.017781079
B19: 4:43-4:48辊印更换F2工作辊！ | H19: 5 | I19: =ROUND(H19/60,1) -> 0.1 | J19: 合计（m³） | L19: =L18+'12-05-26 '!L19:M19 -> 114 | N19: 合计吨钢消耗 （m³/t） | O19: =L19/L10 -> 0.019531742
J20: 原料打包带(น้ำหนักสายรัดวัตถุ) PK | N20: 焊接切除废料(เศษวัสดุหลังการเชื่อม)PK
B21: 6:14-6:20辊印更换F4工作辊！ | H21: 6 | I21: =ROUND(H21/60,1) -> 0.1 | J21: 当日（kg） | L21: 372 | N21: 当日（kg） | O21: 566
J22: 合计（kg） | L22: =L21+'12-05-26 '!L22:M22 -> 4212 | N22: 合计（kg） | O22: =O21+'12-05-26 '!O22 -> 4802
J23: 切头切尾 (scapหัว-ท้าย) | N23: 工艺段及活套废料 (เศษวัสดุจากกระบวนการผลิต)
J24: 当日（kg） | L24: 250 | N24: 当日（kg）
J25: 合计（kg） | L25: =L24+'12-05-26 '!L25:M25 -> 2385 | N25: 合计（kg）
J26: 酸洗天然气( แก๊ส PK)
J27: 当日（Nm3） | L27: 1399 | N27: 当日吨钢消耗 （Nm3/t） | O27: =L27/L9 -> 2.76397
J28: 合计（Nm3） | L28: =L27+'12-05-26 '!L28:M28 -> 17604 | N28: 合计吨钢消耗 （Nm3/t） | O28: =L28/L10 -> 3.0161121
J29: 缓蚀剂 (Actived 1803 )
J30: 当日（L） | L30: 27
J31: 合计(L) | L31: =L30+'12-05-26 '!L31:O31 -> 342
J32: 轧机电耗 (ไฟฟ้า) CRL
I33: =ROUND(I16+I17+I19+I22+I23+I25+I27+I29+I31,1) -> 0.5 | J33: 当日（kwh） | L33: 19164 | N33: 当日吨钢消耗 （kwh/t） | O33: =L33/O9 -> 38.194624
J34: 合计（kwh） | L34: =L33+'12-05-26 '!L34:M34 -> 240478 | N34: 合计吨钢消耗 （kwh/t） | O34: =L34/O10 -> 41.568886
A35: 质量概述 QC | B35: B级品3卷原料边裂！ | J35: 轧机废料 (เศษวัสดุจากเครื่องรีด) | N35: 成材率 (อัตราการผลิต)
J36: 断带废ของเสียจากสายพานขาด（kg） | L36: 126 | M36: =L36+'12-05-26 '!M36 -> 2251 | N36: =L36/1000/L9 -> 0.00024893511 | O36: =M36/1000/L10 -> 0.00038566624
J37: 调整废（kg）ของเสียจากการปรับตั้ง | L37: 210 | M37: =L37+'12-05-26 '!M37 -> 2530 | N37: =L37/1000/L9 -> 0.00041489185 | O37: =M37/1000/L10 -> 0.00043346761
J38: 孔洞、边裂（kg）ของเสียจากขอบแตก | L38: 300 | M38: =L38+'12-05-26 '!M38 -> 2929 | N38: =L38/1000/L9 -> 0.00059270265 | O38: =M38/1000/L10 -> 0.0005018287
J39: 当日（kg） | L39: =L36+L37+L38 -> 636 | N39: 当日（%） | O39: =O9/L9 -> 0.99128727
J40: 合计（kg） | L40: =L39+'12-05-26 '!L40:M40 -> 7710 | N40: 合计（%） | O40: =(O10)/(L10-L22/1000) -> 0.99187424
J41: 轧制油 (Coolant)
...

Sheet 14-05-26
A1: 酸轧线生产运行记录总表 สรุปการผลิต PK CRL Line
M2: 日期 (Date)
A3: 生产数据记录 บันทึกข้อมูลการผลิต | B3: 序号 Item | C3: 生产订单 Production Order | D3: 原料规格 size of material | E3: 原料重量 Weight of material（t） | F3: 原料卷数PK（coil） | G3: 成品规格 Description product | H3: 成品重量 weight of product (t) | I3: 成品卷数 CRL（coil） | J3: 各项指标及能源消耗 (ตัวชี้วัดและการใช้พลังงาน)
B5: 1 | C5: 138100000524 | D5: HRC 4.50 x 389 SPHC | E5: 41374 | F5: 9 | G5: CRC 1.84 x 389 SPCC | H5: 41214 | I5: 9 | J5: B级品 (เกรด B) | N5: 一级品率 (เกรด A)
B6: 2 | C6: 138100000523 | D6: HRC 4.20 x 389 SPHC | E6: 13596 | F6: 3 | G6: CRC 1.84 x 389 SPCC | H6: 13352 | I6: 3 | J6: 当日 /วัน（T） | L6: 8.992 | N6: 当日/ วัน（%） | O6: =(O9-L6)/O9 -> 0.9802762
B7: 3 | C7: 138100000581 | D7: HRL 4.05 x 430 SS400 | E7: 13269 | F7: 2 | G7: CRC 1.30 x 428 SPCC | H7: 12914 | I7: 2 | J7: 合计/ทั้งหมด（T） | L7: =L6+'13-05-26'!L7:M7 -> 173.356 | N7: 合计/ ทั้งหมด（%） | O7: =(O10-L7)/O10 -> 0.97222279
B8: 4 | C8: 138100000526 | D8: HRC 4.50 x 388 SPHC | E8: 383498 | F8: 84 | G8: CRC 2.10 x 388 SPCC | H8: 380600 | I8: 84 | J8: 原料重量 (น้ำหนักวัตถุดิบ) PK | N8: 成品重量 (น้ำหนักวัตถุดิบ) CRL
B9: 5 | C9: 138100000528 | D9: HRC 4.50 x 341 SPHC | E9: 7966 | F9: 2 | G9: CRC 1.84 x 341 SPCC | H9: 7816 | I9: 2 | J9: 当日（t） | L9: 459.703 | N9: 当日（t） | O9: 455.896
J10: 合计（t） | L10: =L9+'13-05-26'!L10:M10 -> 6296.356 | N10: 合计（t） | O10: =O9+'13-05-26'!O10 -> 6240.944
J11: 机时产量(อัตราการผลิต/1ชั่วโมง) | N11: 有效作业率 (อัตราการทำงาน)
J12: 当日（t/h） | L12: =O9/(11-I33) -> 43.418667 | N12: 当日 （%） | O12: =(11-I33)/11 -> 0.95454545
J13: 合计（t/h） | L13: =O10/O46 -> 46.643827 | N13: 合计（%） | O13: =O46/L46 -> 0.93566434
J14: 酸洗电耗 ( ไฟฟ้า) PK
A15: 停机记录 บันทึกการหยุดเครื่อง | B15: 23:02-23:24窄带改宽带更换F1.F2.F3.F4工作辊！ | H15: 分钟 | I15: 小时 | J15: 当日（kwh） | L15: 3607 | N15: 当日吨钢消耗 （kwh/t） | O15: =L15/L9 -> 7.8463704
H16: 22 | I16: =ROUND(H16/60,1) -> 0.4 | J16: 合计（kwh） | L16: =L15+'13-05-26'!L16:M16 -> 43722 | N16: 合计吨钢消耗 （kwh/t） | O16: =L16/L10 -> 6.9440165
B17: 2:06-2:12自动焊机二次焊接！ | H17: 6 | I17: =ROUND(H17/60,1) -> 0.1 | J17: 盐酸 (HCL)
J18: 当日（m³） | L18: 6 | N18: 当日吨钢消耗 （m³/t） | O18: =L18/L9 -> 0.013051905
J19: 合计（m³） | L19: =L18+'13-05-26'!L19:M19 -> 120 | N19: 合计吨钢消耗 （m³/t） | O19: =L19/L10 -> 0.019058643
J20: 原料打包带(น้ำหนักสายรัดวัตถุ) PK | N20: 焊接切除废料(เศษวัสดุหลังการเชื่อม)PK
J21: 当日（kg） | L21: 298 | N21: 当日（kg） | O21: 476
J22: 合计（kg） | L22: =L21+'13-05-26'!L22:M22 -> 4510 | N22: 合计（kg） | O22: =O21+'13-05-26'!O22 -> 5278
J23: 切头切尾 (scapหัว-ท้าย) | N23: 工艺段及活套废料 (เศษวัสดุจากกระบวนการผลิต)
J24: 当日（kg） | L24: 258 | N24: 当日（kg）
J25: 合计（kg） | L25: =L24+'13-05-26'!L25:M25 -> 2643 | N25: 合计（kg）
J26: 酸洗天然气( แก๊ส PK)
J27: 当日（Nm3） | L27: 1348 | N27: 当日吨钢消耗 （Nm3/t） | O27: =L27/L9 -> 2.932328
J28: 合计（Nm3） | L28: =L27+'13-05-26'!L28:M28 -> 18952 | N28: 合计吨钢消耗 （Nm3/t） | O28: =L28/L10 -> 3.009995
J29: 缓蚀剂 (Actived 1803 )
J30: 当日（L） | L30: 18
J31: 合计(L) | L31: =L30+'13-05-26'!L31:O31 -> 360
J32: 轧机电耗 (ไฟฟ้า) CRL
I33: =ROUND(I16+I17+I19+I22+I23+I25+I27+I29+I31,1) -> 0.5 | J33: 当日（kwh） | L33: 18040 | N33: 当日吨钢消耗 （kwh/t） | O33: =L33/O9 -> 39.570428
J34: 合计（kwh） | L34: =L33+'13-05-26'!L34:M34 -> 258518 | N34: 合计吨钢消耗 （kwh/t） | O34: =L34/O10 -> 41.4229
A35: 质量概述 QC | B35: B级品：原料边裂2卷 | J35: 轧机废料 (เศษวัสดุจากเครื่องรีด) | N35: 成材率 (อัตราการผลิต)
J36: 断带废ของเสียจากสายพานขาด（kg） | L36: 418 | M36: =L36+'13-05-26'!M36 -> 2669 | N36: =L36/1000/L9 -> 0.00090928273 | O36: =M36/1000/L10 -> 0.00042389598
J37: 调整废（kg）ของเสียจากการปรับตั้ง | L37: 480 | M37: =L37+'13-05-26'!M37 -> 3010 | N37: =L37/1000/L9 -> 0.0010441524 | O37: =M37/1000/L10 -> 0.00047805429
J38: 孔洞、边裂（kg）ของเสียจากขอบแตก | L38: 386 | M38: =L38+'13-05-26'!M38 -> 3315 | N38: =L38/1000/L9 -> 0.00083967257 | O38: =M38/1000/L10 -> 0.00052649501
J39: 当日（kg） | L39: =L36+L37+L38 -> 1284 | N39: 当日（%） | O39: =O9/L9 -> 0.99171857
J40: 合计（kg） | L40: =L39+'13-05-26'!L40:M40 -> 8994 | N40: 合计（%） | O40: =(O10)/(L10-L22/1000) -> 0.99190985
J41: 轧制油 (Coolant)
...

Sheet 15-05-26
A1: 酸轧线生产运行记录总表 สรุปการผลิต PK CRL Line
M2: 日期 (Date)
A3: 生产数据记录 บันทึกข้อมูลการผลิต | B3: 序号 Item | C3: 生产订单 Production Order | D3: 原料规格 size of material | E3: 原料重量 Weight of material（t） | F3: 原料卷数PK（coil） | G3: 成品规格 Description product | H3: 成品重量 weight of product (t) | I3: 成品卷数 CRL（coil） | J3: 各项指标及能源消耗 (ตัวชี้วัดและการใช้พลังงาน)
B5: 1 | C5: 138100000528 | D5: HRC 4.50 x 341 SPHC | E5: 99277 | F5: 25 | G5: CRC 1.84 x 341 SPCC | H5: 98184 | I5: 25 | J5: B级品 (เกรด B) | N5: 一级品率 (เกรด A)
B6: 2 | C6: 138100000533 | D6: HRC 4.50 x 337 SPHC | E6: 107158 | F6: 27 | G6: CRC 2.10 x 337 SPCC | H6: 106198 | I6: 27 | J6: 当日 /วัน（T） | L6: 25.076 | N6: 当日/ วัน（%） | O6: =(O9-L6)/O9 -> 0.93837155
B7: 3 | D7: HRC 4.50 x 472 SPHC | E7: 5589 | F7: 1 | G7: HRC 4.50 x 472 SPHC | H7: 5552 | I7: 1 | J7: 合计/ทั้งหมด（T） | L7: =L6+'14-05-26'!L7:M7 -> 198.432 | N7: 合计/ ทั้งหมด（%） | O7: =(O10-L7)/O10 -> 0.97015088
B8: 4 | D8: HRC 4.50 x 475 A460LF | E8: 9183 | F8: 2 | G8: HRC 4.50 x 475 SPHC | H8: 9102 | I8: 2 | J8: 原料重量 (น้ำหนักวัตถุดิบ) PK | N8: 成品重量 (น้ำหนักวัตถุดิบ) CRL
B9: 5 | C9: 138100000584 | D9: HRL 5.40 x 428 SS400 | E9: 6110 | F9: 1 | G9: CRC 2.10 x 428 SPCC | H9: 5642 | I9: 1 | J9: 当日（t） | L9: 412.758 | N9: 当日（t） | O9: 406.89
B10: 6 | C10: 138100000585 | D10: HRC 3.06 x 464 SPHC | E10: 185441 | F10: 33 | G10: CRC 1.30 x 464 SPCC | H10: 183212 | I10: 33 | J10: 合计（t） | L10: =L9+'14-05-26'!L10:M10 -> 6709.114 | N10: 合计（t） | O10: =O9+'14-05-26'!O10 -> 6647.834
J11: 机时产量(อัตราการผลิต/1ชั่วโมง) | N11: 有效作业率 (อัตราการทำงาน)
J12: 当日（t/h） | L12: =O9/(11-I33) -> 41.947423 | N12: 当日 （%） | O12: =(11-I33)/11 -> 0.88181818
J13: 合计（t/h） | L13: =O10/O46 -> 46.326369 | N13: 合计（%） | O13: =O46/L46 -> 0.93181818
J14: 酸洗电耗 ( ไฟฟ้า) PK
A15: 停机记录 บันทึกการหยุดเครื่อง | B15: 2:18-2:23一号开卷机故障上料跟不上！ | H15: 分钟 | I15: 小时 | J15: 当日（kwh） | L15: 3452 | N15: 当日吨钢消耗 （kwh/t） | O15: =L15/L9 -> 8.363254
H16: 5 | I16: =ROUND(H16/60,1) -> 0.1 | J16: 合计（kwh） | L16: =L15+'14-05-26'!L16:M16 -> 47174 | N16: 合计吨钢消耗 （kwh/t） | O16: =L16/L10 -> 7.0313308
B17: 3:10-4:15酸洗3件热轧带钢不冷轧，更换F1.F2.F3.F4工作辊窄带改宽带！ | H17: 65 | I17: =ROUND(H17/60,1) -> 1.1 | J17: 盐酸 (HCL)
J18: 当日（m³） | L18: 9 | N18: 当日吨钢消耗 （m³/t） | O18: =L18/L9 -> 0.021804544
B19: 5:03-5:09辊印更换F4工作辊！ | H19: 6 | I19: =ROUND(H19/60,1) -> 0.1 | J19: 合计（m³） | L19: =L18+'14-05-26'!L19:M19 -> 129 | N19: 合计吨钢消耗 （m³/t） | O19: =L19/L10 -> 0.019227576
J20: 原料打包带(น้ำหนักสายรัดวัตถุ) PK | N20: 焊接切除废料(เศษวัสดุหลังการเชื่อม)PK
B21: 6:29-7:04五六S辊故障F1入口断带，更换F1.F2.F3.F4工作辊！ | H21: 35 | I21: =ROUND(H21/60,1) -> 0.6 | J21: 当日（kg） | L21: 268 | N21: 当日（kg） | O21: 342
J22: 合计（kg） | L22: =L21+'14-05-26'!L22:M22 -> 4778 | N22: 合计（kg） | O22: =O21+'14-05-26'!O22 -> 5620
J23: 切头切尾 (scapหัว-ท้าย) | N23: 工艺段及活套废料 (เศษวัสดุจากกระบวนการผลิต)
J24: 当日（kg） | L24: 200 | N24: 当日（kg）
J25: 合计（kg） | L25: =L24+'14-05-26'!L25:M25 -> 2843 | N25: 合计（kg）
J26: 酸洗天然气( แก๊ส PK)
J27: 当日（Nm3） | L27: 1409 | N27: 当日吨钢消耗 （Nm3/t） | O27: =L27/L9 -> 3.4136225
J28: 合计（Nm3） | L28: =L27+'14-05-26'!L28:M28 -> 20361 | N28: 合计吨钢消耗 （Nm3/t） | O28: =L28/L10 -> 3.034827
J29: 缓蚀剂 (Actived 1803 )
J30: 当日（L） | L30: 27
J31: 合计(L) | L31: =L30+'14-05-26'!L31:O31 -> 387
J32: 轧机电耗 (ไฟฟ้า) CRL
I33: =ROUND(I16+I17+I19+I22+I23+I25+I27+I29+I31,1) -> 1.3 | J33: 当日（kwh） | L33: 17141 | N33: 当日吨钢消耗 （kwh/t） | O33: =L33/O9 -> 42.126865
J34: 合计（kwh） | L34: =L33+'14-05-26'!L34:M34 -> 275659 | N34: 合计吨钢消耗 （kwh/t） | O34: =L34/O10 -> 41.465987
A35: 质量概述 QC | B35: 原料边裂5卷 | J35: 轧机废料 (เศษวัสดุจากเครื่องรีด) | N35: 成材率 (อัตราการผลิต)
J36: 断带废ของเสียจากสายพานขาด（kg） | L36: 152 | M36: =L36+'14-05-26'!M36 -> 2821 | N36: =L36/1000/L9 -> 0.00036825452 | O36: =M36/1000/L10 -> 0.00042047281
J37: 调整废（kg）ของเสียจากการปรับตั้ง | L37: 486 | M37: =L37+'14-05-26'!M37 -> 3496 | N37: =L37/1000/L9 -> 0.0011774454 | O37: =M37/1000/L10 -> 0.00052108222
J38: 孔洞、边裂（kg）ของเสียจากขอบแตก | L38: 396 | M38: =L38+'14-05-26'!M38 -> 3711 | N38: =L38/1000/L9 -> 0.00095939994 | O38: =M38/1000/L10 -> 0.00055312818
J39: 当日（kg） | L39: =L36+L37+L38 -> 1034 | N39: 当日（%） | O39: =O9/L9 -> 0.98578344
J40: 合计（kg） | L40: =L39+'14-05-26'!L40:M40 -> 10028 | N40: 合计（%） | O40: =(O10)/(L10-L22/1000) -> 0.99157232
J41: 轧制油 (Coolant)
...

Sheet 16-05-26
A1: 酸轧线生产运行记录总表 สรุปการผลิต PK CRL Line
M2: 日期 (Date)
A3: 生产数据记录 บันทึกข้อมูลการผลิต | B3: 序号 Item | C3: 生产订单 Production Order | D3: 原料规格 size of material | E3: 原料重量 Weight of material（t） | F3: 原料卷数PK（coil） | G3: 成品规格 Description product | H3: 成品重量 weight of product (t) | I3: 成品卷数 CRL（coil） | J3: 各项指标及能源消耗 (ตัวชี้วัดและการใช้พลังงาน)
B5: 1 | C5: 138100000585 | D5: HRC 3.06 x 464 SPHC | E5: 117179 | F5: 21 | G5: CRC 1.30 x 464 SPCC | H5: 116234 | I5: 21 | J5: B级品 (เกรด B) | N5: 一级品率 (เกรด A)
B6: 2 | C6: 138100000586 | D6: HRC 3.06 x 464 SPHC | E6: 316955 | F6: 56 | G6: CRC 1.11 x 464 SPCC | H6: 314854 | I6: 56 | J6: 当日 /วัน（T） | L6: 56.02 | N6: 当日/ วัน（%） | O6: =(O9-L6)/O9 -> 0.87895053
